Workbook

Sheet Raw P&L
A1: Years Ended | B1: 2021 | C1: 2022 | D1: 2023 | E1: 2024 | F1: 2025
A2: Net revenue | B2: 79024 | C2: 63054 | D2: 54228 | E2: 53101 | F2: 52853
A3: Cost of sales | B3: 35209 | C3: 36188 | D3: 32517 | E3: 35756 | F3: 34478
A4: Gross profit | B4: 43815 | C4: 26866 | D4: 21711 | E4: 17345 | F4: 18375
A5: Research and development | B5: 15190 | C5: 17528 | D5: 16046 | E5: 16546 | F5: 13774
A6: Marketing, general and administrative | B6: 6543 | C6: 7002 | D6: 5634 | E6: 5507 | F6: 4624
A7: Restructuring and other charges | B7: 2626 | C7: 2 | D7: -62 | E7: 6970 | F7: 2191
A8: Operating expenses | B8: 24359 | C8: 24532 | D8: 21618 | E8: 29023 | F8: 20589
A9: Operating income (loss) | B9: 19456 | C9: 2334 | D9: 93 | E9: -11678 | F9: -2214
A10: Gains (losses) on equity investments, net | B10: 2729 | C10: 4268 | D10: 40 | E10: 242 | F10: 514
A11: Interest and other, net | B11: -482 | C11: 1166 | D11: 629 | E11: 226 | F11: 3257
A12: Income (loss) before taxes | B12: 21703 | C12: 7768 | D12: 762 | E12: -11210 | F12: 1557
... A20: Weighted average shares of common stock outstanding — Diluted | B20: 4090 | C20: 4123 | D20: 4212 | E20: 4280 | F20: 4530

Sheet Raw Comprehensive Income (Loss)
A1: Years Ended | B1: 2021 | C1: 2022 | D1: 2023 | E1: 2024 | F1: 2025
A2: Net income (loss) | B2: 19868 | C2: 8017 | D2: 1675 | E2: -19233 | F2: 26
A3: Changes in other comprehensive income (loss), net of tax:
A4: Net unrealized holding gains (losses) on derivatives | B4: -520 | C4: -510 | D4: 272 | E4: -555 | F4: 743
A5: Actuarial valuation and other pension benefits (expenses), net | B5: 451 | C5: 855 | D5: 66 | E5: 60 | F5: 78
A6: Translation adjustments and other | B6: -60 | C6: -27 | D6: 9 | E6: -1 | F6: 3
A7: Other comprehensive income (loss) | B7: -129 | C7: 318 | D7: 347 | E7: -496 | F7: 824
A8: Total comprehensive income (loss) | B8: 19739 | C8: 8335 | D8: 2022 | E8: -19729 | F8: 850
A9: Less: comprehensive income (loss) attributable to non-controlling interests | B9: 3 | C9: 3 | D9: -14 | E9: -477 | F9: 293
A10: Total comprehensive income (loss) attributable to Intel | B10: 19739 | C10: 8332 | D10: 2036 | E10: -19252 | F10: 557

Sheet Raw Balance Sheet
A1: Years Ended | B1: Dec 25, 2021 | C1: Dec 31, 2022 | D1: Dec 30, 2023 | E1: Dec 28, 2024 | F1: Dec 27, 2025
A2: Assets
A3: Cash and cash equivalents | B3: 4827 | C3: 11144 | D3: 7079 | E3: 8249 | F3: 14265
A4: Short-term investments | B4: 24426 | C4: 17194 | D4: 17955 | E4: 13813 | F4: 23151
A5: Accounts receivable, net | B5: 9457 | C5: 4133 | D5: 3402 | E5: 3478 | F5: 3839
A6: Inventories | B6: 10776 | C6: 13224 | D6: 11127 | E6: 12198 | F6: 11618
A7: Assets held for sale | B7: 6942 | C7: 0 | D7: 0 | E7: 0 | F7: 0
A8: Other current assets | B8: 2130 | C8: 4712 | D8: 3706 | E8: 9586 | F8: 10815
A9: Total current assets | B9: 58555 | C9: 50407 | D9: 43269 | E9: 47324 | F9: 63688
A10: Property, plant and equipment, net | B10: 63245 | C10: 80860 | D10: 96647 | E10: 107919 | F10: 105414
A11: Equity investments | B11: 6298 | C11: 5912 | D11: 5829 | E11: 5383 | F11: 8512
A12: Goodwill | B12: 26963 | C12: 27591 | D12: 27591 | E12: 24693 | F12: 23912
A13: Identified intangible assets, net | B13: 7270 | C13: 6018 | D13: 4589 | E13: 3691 | F13: 2772
A14: Other long-term assets | B14: 6072 | C14: 11315 | D14: 13647 | E14: 7475 | F14: 7131
A15: Total assets | B15: 168406 | C15: 182103 | D15: 191572 | E15: 196485 | F15: 211429
A16: Liabilities and stockholders' equity
A17: Short-term debt | B17: 4591 | C17: 4367 | D17: 2288 | E17: 3729 | F17: 2499
A18: Accounts payable | B18: 5747 | C18: 9595 | D18: 8578 | E18: 12556 | F18: 9882
A19: Accrued compensation and benefits | B19: 4535 | C19: 4084 | D19: 3655 | E19: 3343 | F19: 3990
A20: Income taxes payable | B20: 1076 | C20: 2251 | D20: 1107 | E20: 1756 | F20: 604
A21: Other accrued liabilities | B21: 11513 | C21: 11858 | D21: 12425 | E21: 14282 | F21: 14600
A22: Total current liabilities | B22: 27462 | C22: 32155 | D22: 28053 | E22: 35666 | F22: 31575
A23: Debt | B23: 33510 | C23: 37684 | D23: 46978 | E23: 46282 | F23: 44086
A24: Long-term income taxes payable | B24: 4305 | C24: 3796 | D24: 0 | E24: 0 | F24: 0
A25: Deferred income tax | B25: 2667 | C25: 202 | D25: 0 | E25: 0 | F25: 0
A26: Other long-term liabilities | B26: 5071 | C26: 4980 | D26: 6576 | E26: 9505 | F26: 9408
A27: Total liabilities | B27: 72015 | C27: 78817 | D27: 81607 | E27: 91453 | F27: 85069
A28: Common stock and additional paid-in capital | B28: 28006 | C28: 31580 | D28: 36649 | E28: 50949 | F28: 65185
... A34: Total liabilities and stockholders' equity | B34: 168406 | C34: 182103 | D34: 191572 | E34: 196485 | F34: 211429

Sheet Raw Cash Flow
A1: Years Ended | B1: Dec 25, 2021 | C1: Dec 31, 2022 | D1: Dec 30, 2023 | E1: Dec 28, 2024 | F1: Dec 27, 2025
A2: Cash and cash equivalents, beginning of period | B2: 5865 | C2: 4827 | D2: 11144 | E2: 7079 | F2: 8249
A3: Cash flows provided by (used for) operating activities:
A4: Net income (loss) | B4: 19868 | C4: 8017 | D4: 1675 | E4: -19233 | F4: 26
A5: Depreciation | B5: 9953 | C5: 11128 | D5: 7847 | E5: 9951 | F5: 10757
A6: Share-based compensation | B6: 2036 | C6: 3128 | D6: 3229 | E6: 3410 | F6: 4234
A7: Restructuring and other charges | B7: 2626 | C7: 1074 | D7: -424 | E7: 3491 | F7: 476
A8: Amortization of intangibles | B8: 1839 | C8: 1907 | D8: 1755 | E8: 1428 | F8: 949
A9: (Gains) losses on equity investments, net | B9: -1458 | C9: -4254 | D9: -42 | E9: -246 | F9: -514
A10: (Gains) losses on divestitures | B10: 0 | C10: -1059 | D10: 0 | E10: 0 | F10: -5323
A11: Mark-to-market (gains) losses on Escrowed Shares | B11: 0 | C11: 0 | D11: 0 | E11: 0 | F11: 1796
A12: Deferred taxes | B12: 0 | C12: 0 | D12: -2033 | E12: 6132 | F12: 328
A13: Impairments and net (gain) loss on retirement of property, plant and equipment | B13: 0 | C13: 0 | D13: 33 | E13: 2252 | F13: 515
A14: Accounts receivable | B14: -2674 | C14: 5327 | D14: 731 | E14: -75 | F14: -449
A15: Inventories | B15: -2339 | C15: -2436 | D15: 2097 | E15: -1105 | F15: -138
... A21: Net cash provided by operating activities | B21: 29456 | C21: 15433 | D21: 11471 | E21: 8288 | F21: 9697
A22: Cash flows provided by (used for) investing activities:
A23: Additions to property, plant and equipment | B23: -18733 | C23: -24844 | D23: -25750 | E23: -23944 | F23: -14646
A24: Proceeds from capital-related government incentives | B24: -1596 | C24: -206 | D24: 1011 | E24: 1936 | F24: 1577
A25: Purchases of short-term investments | B25: -40554 | C25: -43647 | D25: -44414 | E25: -37940 | F25: -24319
A26: Maturities and sales of short-term investments | B26: 35299 | C26: 48730 | D26: 44077 | E26: 41463 | F26: 15387
A27: Sales of equity investments | B27: -613 | C27: -510 | D27: 0 | E27: 1047 | F27: 671
A28: Proceeds from divestitures, net | B28: 0 | C28: 4961 | D28: 0 | E28: 0 | F28: 6157
A29: Other investing | B29: 1167 | C29: -1540 | D29: 563 | E29: -818 | F29: 352
A30: Net cash used for investing activities | B30: -24449 | C30: -10477 | D30: -24041 | E30: -18256 | F30: -14821
A31: Cash flows provided by (used for) financing activities:
A32: Issuance of commercial paper, net of issuance costs | B32: — | C32: 3945 | D32: — | E32: 7349 | F32: 3493
A33: Repayment of commercial paper | B33: — | C33: — | D33: -3944 | E33: -7349 | F33: -3493
A34: Partner contributions | B34: — | C34: 874 | D34: 1511 | E34: 2714 | F34: 5108
A35: Net proceeds from sales of subsidiary shares | B35: — | C35: — | D35: 2959 | E35: — | F35: 921
A36: Additions to property, plant and equipment | B36: — | C36: — | D36: — | E36: -1178 | F36: -3026
A37: Issuance of long-term debt, net of issuance costs | B37: 4974 | C37: 6548 | D37: 11391 | E37: 2975 | F37: —
A38: Repayment of debt | B38: -2500 | C38: -4984 | D38: -1423 | E38: -2288 | F38: -3750
A39: Proceeds from sales of common stock through employee equity incentive plans | B39: 1020 | C39: 977 | D39: 1042 | E39: 987 | F39: 771
A40: Net proceeds attributable to common stock and warrants issued, and Escrowed Shares | B40: — | C40: — | D40: — | E40: — | F40: 12706
A41: Restricted stock unit withholdings | B41: -1480 | C41: -989 | D41: -534 | E41: -631 | F41: -423
A42: Payment of dividends to stockholders | B42: -5644 | C42: -5997 | D42: -3088 | E42: -1599 | F42: —
A43: Other financing | B43: -1480 | C43: -689 | D43: -409 | E43: 158 | F43: -720
A44: Net cash provided by financing activities | B44: -6045 | C44: 1361 | D44: 8505 | E44: 11138 | F44: 11587
A45: Net increase (decrease) in cash and cash equivalents | B45: -1038 | C45: 6317 | D45: -4065 | E45: 1170 | F45: 6463
...

Sheet Summarized Statements
A1: Income Statement | B1: 2021 | C1: 2022 | D1: 2023 | E1: 2024 | F1: 2025
A2: Revenues | B2: ='Raw P&L'!B$2 -> 79024 | C2: ='Raw P&L'!C$2 -> 63054 | D2: ='Raw P&L'!D$2 -> 54228 | E2: ='Raw P&L'!E$2 -> 53101 | F2: ='Raw P&L'!F$2 -> 52853
A3: Cost of Goods Sold (COGS) | B3: ='Raw P&L'!B$3 -> 35209 | C3: ='Raw P&L'!C$3 -> 36188 | D3: ='Raw P&L'!D$3 -> 32517 | E3: ='Raw P&L'!E$3 -> 35756 | F3: ='Raw P&L'!F$3 -> 34478
A4: Gross profit | B4: =B2-B3 -> 43815 | C4: =C2-C3 -> 26866 | D4: =D2-D3 -> 21711 | E4: =E2-E3 -> 17345 | F4: =F2-F3 -> 18375
A5: Operating Expenses
A6: Research & Development | B6: ='Raw P&L'!B$5 -> 15190 | C6: ='Raw P&L'!C$5 -> 17528 | D6: ='Raw P&L'!D$5 -> 16046 | E6: ='Raw P&L'!E$5 -> 16546 | F6: ='Raw P&L'!F$5 -> 13774
A7: SG&A | B7: ='Raw P&L'!B$6+'Raw P&L'!B$7 -> 9169 | C7: ='Raw P&L'!C$6+'Raw P&L'!C$7 -> 7004 | D7: ='Raw P&L'!D$6+'Raw P&L'!D$7 -> 5572 | E7: ='Raw P&L'!E$6+'Raw P&L'!E$7 -> 12477 | F7: ='Raw P&L'!F$6+'Raw P&L'!F$7 -> 6815
A8: Total Operating Expenses | B8: =B6+B7 -> 24359 | C8: =C6+C7 -> 24532 | D8: =D6+D7 -> 21618 | E8: =E6+E7 -> 29023 | F8: =F6+F7 -> 20589
A9: EBIT (Operating Income) | B9: =B4-B8 -> 19456 | C9: =C4-C8 -> 2334 | D9: =D4-D8 -> 93 | E9: =E4-E8 -> -11678 | F9: =F4-F8 -> -2214
A10: Gains (losses) on equity investments, net | B10: ='Raw P&L'!B10 -> 2729 | C10: ='Raw P&L'!C10 -> 4268 | D10: ='Raw P&L'!D10 -> 40 | E10: ='Raw P&L'!E10 -> 242 | F10: ='Raw P&L'!F10 -> 514
A11: Interest & Other (net) | B11: ='Raw P&L'!B$11 -> -482 | C11: ='Raw P&L'!C$11 -> 1166 | D11: ='Raw P&L'!D$11 -> 629 | E11: ='Raw P&L'!E$11 -> 226 | F11: ='Raw P&L'!F$11 -> 3257
A12: EBT | B12: =B9+B10+B11 -> 21703 | C12: =C9+C10+C11 -> 7768 | D12: =D9+D10+D11 -> 762 | E12: =E9+E10+E11 -> -11210 | F12: =F9+F10+F11 -> 1557
A13: Taxes | B13: ='Raw P&L'!B13 -> 1835 | C13: ='Raw P&L'!C13 -> -249 | D13: ='Raw P&L'!D13 -> -913 | E13: ='Raw P&L'!E13 -> 8023 | F13: ='Raw P&L'!F13 -> 1531
A14: Net Earnings | B14: =B12-B13 -> 19868 | C14: =C12-C13 -> 8017 | D14: =D12-D13 -> 1675 | E14: =E12-E13 -> -19233 | F14: =F12-F13 -> 26
A18: Balance Sheet | B18: 2021 | C18: 2022 | D18: 2023 | E18: 2024 | F18: 2025
A20: Assets
A21: Cash & Cash Equivalents | B21: ='Raw Balance Sheet'!B$3 -> 4827 | C21: ='Raw Balance Sheet'!C$3 -> 11144 | D21: ='Raw Balance Sheet'!D$3 -> 7079 | E21: ='Raw Balance Sheet'!E$3 -> 8249 | F21: ='Raw Balance Sheet'!F$3 -> 14265
A22: Short-Term Investments | B22: ='Raw Balance Sheet'!B$4 -> 24426 | C22: ='Raw Balance Sheet'!C$4 -> 17194 | D22: ='Raw Balance Sheet'!D$4 -> 17955 | E22: ='Raw Balance Sheet'!E$4 -> 13813 | F22: ='Raw Balance Sheet'!F$4 -> 23151
A23: Accounts Receivable | B23: ='Raw Balance Sheet'!B$5 -> 9457 | C23: ='Raw Balance Sheet'!C$5 -> 4133 | D23: ='Raw Balance Sheet'!D$5 -> 3402 | E23: ='Raw Balance Sheet'!E$5 -> 3478 | F23: ='Raw Balance Sheet'!F$5 -> 3839
A24: Inventory | B24: ='Raw Balance Sheet'!B$6 -> 10776 | C24: ='Raw Balance Sheet'!C$6 -> 13224 | D24: ='Raw Balance Sheet'!D$6 -> 11127 | E24: ='Raw Balance Sheet'!E$6 -> 12198 | F24: ='Raw Balance Sheet'!F$6 -> 11618
A25: Assets Held for Sale | B25: ='Raw Balance Sheet'!B$7 -> 6942 | C25: ='Raw Balance Sheet'!C$7 -> 0 | D25: ='Raw Balance Sheet'!D$7 -> 0 | E25: ='Raw Balance Sheet'!E$7 -> 0 | F25: ='Raw Balance Sheet'!F$7 -> 0
A26: Other Current Assets | B26: ='Raw Balance Sheet'!B$8 -> 2130 | C26: ='Raw Balance Sheet'!C$8 -> 4712 | D26: ='Raw Balance Sheet'!D$8 -> 3706 | E26: ='Raw Balance Sheet'!E$8 -> 9586 | F26: ='Raw Balance Sheet'!F$8 -> 10815
A27: Total Current Assets | B27: =SUM(B21:B26) -> 58558 | C27: =SUM(C21:C26) -> 50407 | D27: =SUM(D21:D26) -> 43269 | E27: =SUM(E21:E26) -> 47324 | F27: =SUM(F21:F26) -> 63688
A29: PP&E (Net) | B29: ='Raw Balance Sheet'!B$10 -> 63245 | C29: ='Raw Balance Sheet'!C$10 -> 80860 | D29: ='Raw Balance Sheet'!D$10 -> 96647 | E29: ='Raw Balance Sheet'!E$10 -> 107919 | F29: ='Raw Balance Sheet'!F$10 -> 105414
A30: Equity Investments | B30: ='Raw Balance Sheet'!B$11 -> 6298 | C30: ='Raw Balance Sheet'!C$11 -> 5912 | D30: ='Raw Balance Sheet'!D$11 -> 5829 | E30: ='Raw Balance Sheet'!E$11 -> 5383 | F30: ='Raw Balance Sheet'!F$11 -> 8512
A31: Goodwill | B31: ='Raw Balance Sheet'!B$12 -> 26963 | C31: ='Raw Balance Sheet'!C$12 -> 27591 | D31: ='Raw Balance Sheet'!D$12 -> 27591 | E31: ='Raw Balance Sheet'!E$12 -> 24693 | F31: ='Raw Balance Sheet'!F$12 -> 23912
A32: Identified Intangible Assets | B32: ='Raw Balance Sheet'!B$13 -> 7270 | C32: ='Raw Balance Sheet'!C$13 -> 6018 | D32: ='Raw Balance Sheet'!D$13 -> 4589 | E32: ='Raw Balance Sheet'!E$13 -> 3691 | F32: ='Raw Balance Sheet'!F$13 -> 2772
A33: Other Long-Term Assets | B33: ='Raw Balance Sheet'!B$14 -> 6072 | C33: ='Raw Balance Sheet'!C$14 -> 11315 | D33: ='Raw Balance Sheet'!D$14 -> 13647 | E33: ='Raw Balance Sheet'!E$14 -> 7475 | F33: ='Raw Balance Sheet'!F$14 -> 7131
A34: Total Assets | B34: =SUM(B27:B33) -> 168406 | C34: =SUM(C27:C33) -> 182103 | D34: =SUM(D27:D33) -> 191572 | E34: =SUM(E27:E33) -> 196485 | F34: =SUM(F27:F33) -> 211429
A36: Liabilities
A37: Accounts Payable | B37: ='Raw Balance Sheet'!B18 -> 5747 | C37: ='Raw Balance Sheet'!C18 -> 9595 | D37: ='Raw Balance Sheet'!D18 -> 8578 | E37: ='Raw Balance Sheet'!E18 -> 12556 | F37: ='Raw Balance Sheet'!F18 -> 9882
A38: Accrued Compensation & Benefits | B38: ='Raw Balance Sheet'!B$19 -> 4535 | C38: ='Raw Balance Sheet'!C$19 -> 4084 | D38: ='Raw Balance Sheet'!D$19 -> 3655 | E38: ='Raw Balance Sheet'!E$19 -> 3343 | F38: ='Raw Balance Sheet'!F$19 -> 3990
A39: Income Taxes Payable | B39: ='Raw Balance Sheet'!B20 -> 1076 | C39: ='Raw Balance Sheet'!C20 -> 2251 | D39: ='Raw Balance Sheet'!D20 -> 1107 | E39: ='Raw Balance Sheet'!E20 -> 1756 | F39: ='Raw Balance Sheet'!F20 -> 604
A40: Other Accrued Liabilities | B40: ='Raw Balance Sheet'!B$21 -> 11513 | C40: ='Raw Balance Sheet'!C$21 -> 11858 | D40: ='Raw Balance Sheet'!D$21 -> 12425 | E40: ='Raw Balance Sheet'!E$21 -> 14282 | F40: ='Raw Balance Sheet'!F$21 -> 14600
A41: Short-Term Debt | B41: ='Raw Balance Sheet'!B$17 -> 4591 | C41: ='Raw Balance Sheet'!C$17 -> 4367 | D41: ='Raw Balance Sheet'!D$17 -> 2288 | E41: ='Raw Balance Sheet'!E$17 -> 3729 | F41: ='Raw Balance Sheet'!F$17 -> 2499
A42: Total Current Liabilities | B42: =SUM(B37:B41) -> 27462 | C42: =SUM(C37:C41) -> 32155 | D42: =SUM(D37:D41) -> 28053 | E42: =SUM(E37:E41) -> 35666 | F42: =SUM(F37:F41) -> 31575
A44: Long-Term Debt | B44: ='Raw Balance Sheet'!B23 -> 33510 | C44: ='Raw Balance Sheet'!C23 -> 37684 | D44: ='Raw Balance Sheet'!D23 -> 46978 | E44: ='Raw Balance Sheet'!E23 -> 46282 | F44: ='Raw Balance Sheet'!F23 -> 44086
A45: Long-Term Income Taxes Payable | B45: ='Raw Balance Sheet'!B$24 -> 4305 | C45: ='Raw Balance Sheet'!C$24 -> 3796 | D45: ='Raw Balance Sheet'!D$24 -> 0 | E45: ='Raw Balance Sheet'!E$24 -> 0 | F45: ='Raw Balance Sheet'!F$24 -> 0
A46: Deferred Income Taxes | B46: ='Raw Balance Sheet'!B$25 -> 2667 | C46: ='Raw Balance Sheet'!C$25 -> 202 | D46: ='Raw Balance Sheet'!D$25 -> 0 | E46: ='Raw Balance Sheet'!E$25 -> 0 | F46: ='Raw Balance Sheet'!F$25 -> 0
A47: Other Long-Term Liabilities | B47: ='Raw Balance Sheet'!B$26 -> 5071 | C47: ='Raw Balance Sheet'!C$26 -> 4980 | D47: ='Raw Balance Sheet'!D$26 -> 6576 | E47: ='Raw Balance Sheet'!E$26 -> 9505 | F47: ='Raw Balance Sheet'!F$26 -> 9408
...

Sheet Formula Sheet
A1: Statement | B1: Summarized Item | C1: Raw Statement | D1: Raw Line Item(s) | E1: Calculation Logic
A2: Income Statement | B2: Revenues | C2: Raw P&L | D2: Net revenue | E2: Direct link
A3: Income Statement | B3: COGS | C3: Raw P&L | D3: Cost of sales | E3: Direct link
A4: Income Statement | B4: Gross Profit | C4: Summarized | D4: Revenues - COGS | E4: Calculated
A5: Income Statement | B5: Research & Development | C5: Raw P&L | D5: Research and development | E5: Direct link
A6: Income Statement | B6: SG&A | C6: Raw P&L | D6: Marketing, general & administrative (+ Restructuring optional) | E6: Aggregated direct link
A7: Income Statement | B7: Total Operating Expenses | C7: Summarized | D7: R&D + SG&A | E7: Sum of summarized lines
A8: Income Statement | B8: EBIT (Operating Income) | C8: Raw P&L | D8: Operating income (loss) | E8: Direct link
A9: Income Statement | B9: Gains (losses) on equity investments, net | C9: Raw P&L | D9: Gains (losses) on equity investments, net | E9: Direct link
A10: Income Statement | B10: Interest & Other (net) | C10: Raw P&L | D10: Interest and other, net | E10: Direct link
A11: Income Statement | B11: EBT | C11: Summarized | D11: EBIT + Gains + Interest | E11: Calculated subtotal
A12: Income Statement | B12: Taxes | C12: Raw P&L | D12: Provision for (benefit from) taxes | E12: Direct link
... A62: Cash Flow | B62: Ending Cash | C62: Summarized | D62: Beginning Cash + Net Change | E62: Calculated check
