Workbook

Sheet Introduction
D2: Introduction & Information
A5: All previous financial data were taked from Nvidia Annual Reports (Income Statement & Balance Sheet & Cash Flow) - All publicly available
A7: Purpose of creating this model is purely for personal development & practice & curiosity - All forecasted numbers are based on personal analysis & opinion
A9: MODEL AND FINANCIAL DATA DO NOT CONTAIN ANY SENSITIVE DATA & ANY FINANCIAL ADVICE
A11: Please do not publish the model anywhere. But if you are interested in using or developing the model for your personal development & curiosity, feel free
A13: If you`d like to discuss the model or have any questions about assumptions & formulas, please contact me
A15: Enjoy Exploring!
A17: Best Regards,
A18: Berk Tansuker
A20: Github
A21: LinkedIn
A22: E-Mail

Sheet Raw P&L
A1: Years ended | B1: Jan 31, 2021 | C1: Jan 30, 2022 | D1: Jan 29, 2023 | E1: Jan 28, 2024 | F1: Jan 26, 2025
A2: Revenue | B2: 16675 | C2: 26914 | D2: 26974 | E2: 60922 | F2: 130497
A3: Cost of revenue | B3: 6279 | C3: 9439 | D3: 11618 | E3: 16621 | F3: 32639
A4: Gross profit | B4: 10396 | C4: 17475 | D4: 15356 | E4: 44301 | F4: 97858
A5: Operating expenses:
A6: Research and development | B6: 3924 | C6: 5268 | D6: 7339 | E6: 8675 | F6: 12914
A7: Sales, general and administrative | B7: 1940 | C7: 2166 | D7: 2440 | E7: 2654 | F7: 3491
A8: Acquisition termination cost | B8: 0 | C8: 0 | D8: 1353 | E8: 0 | F8: 0
A9: Total operating expenses | B9: 5864 | C9: 7434 | D9: 11132 | E9: 11329 | F9: 16405
A10: Operating income / Income from operations | B10: 4532 | C10: 10041 | D10: 4224 | E10: 32972 | F10: 81453
A11: Interest income | B11: 57 | C11: 29 | D11: 267 | E11: 866 | F11: 1786
A12: Interest expense | B12: -184 | C12: -236 | D12: -262 | E12: -257 | F12: -247
A13: Other, net | B13: 4 | C13: 107 | D13: -48 | E13: 237 | F13: 1034
A14: Other income (expense), net | B14: -123 | C14: -100 | D14: -43 | E14: 846 | F14: 2573
A15: Income before income tax | B15: 4409 | C15: 9941 | D15: 4181 | E15: 33818 | F15: 84026
A16: Income tax expense (benefit) | B16: 77 | C16: 189 | D16: -187 | E16: 4058 | F16: 11146
A17: Net income | B17: 4332 | C17: 9752 | D17: 4368 | E17: 29760 | F17: 72880
A18: Net income per share:
A19: Basic | B19: 1.76 | C19: 3.91 | D19: 0.18 | E19: 1.21 | F19: 2.97
A20: Diluted | B20: 1.73 | C20: 3.85 | D20: 0.17 | E20: 1.19 | F20: 2.94
A21: Weighted average shares used in per share computation:
A22: Basic | B22: 2467 | C22: 2496 | D22: 2487 | E22: 2469 | F22: 2455
A23: Diluted | B23: 2510 | C23: 2535 | D23: 2507 | E23: 2494 | F23: 2480

Sheet Raw Balance Sheet
A1: Years ended | B1: Jan 26, 2020 | C1: Jan 31, 2021 | D1: Jan 30, 2022 | E1: Jan 29, 2023 | F1: Jan 28, 2024 | G1: Jan 26, 2025
A2: ASSETS
A3: Current assets:
A4: Cash and cash equivalents | B4: 10896 | C4: 847 | D4: 1990 | E4: 3389 | F4: 7280 | G4: 8589
A5: Marketable securities | B5: 1 | C5: 10714 | D5: 19218 | E5: 9907 | F5: 18704 | G5: 34621
A6: Accounts receivable, net | B6: 1657 | C6: 2429 | D6: 4650 | E6: 3827 | F6: 9999 | G6: 23065
A7: Inventories | B7: 979 | C7: 1826 | D7: 2605 | E7: 5159 | F7: 5282 | G7: 10080
A8: Prepaid expenses and other current assets | B8: 157 | C8: 239 | D8: 366 | E8: 791 | F8: 3080 | G8: 3771
A9: Total current assets | B9: 13690 | C9: 16055 | D9: 28829 | E9: 23073 | F9: 44345 | G9: 80126
A10: Property and equipment, net | B10: 1674 | C10: 2149 | D10: 2778 | E10: 3807 | F10: 3914 | G10: 6283
A11: Operating lease assets | B11: 618 | C11: 707 | D11: 829 | E11: 1038 | F11: 1346 | G11: 1793
A12: Goodwill | B12: 618 | C12: 4193 | D12: 4349 | E12: 4372 | F12: 4430 | G12: 5188
A13: Intangible assets, net | B13: 49 | C13: 2737 | D13: 2339 | E13: 1676 | F13: 1112 | G13: 807
A14: Deferred income tax assets | B14: 548 | C14: 806 | D14: 1222 | E14: 3396 | F14: 6081 | G14: 10979
A15: Other assets | B15: 118 | C15: 2144 | D15: 3841 | E15: 3820 | F15: 4500 | G15: 6425
A16: Total assets | B16: 17315 | C16: 28791 | D16: 44187 | E16: 41182 | F16: 65728 | G16: 111601
A17: LIABILITIES AND SHAREHOLDERS' EQUITY
A18: Current liabilities:
A19: Accounts payable | B19: 687 | C19: 1201 | D19: 1783 | E19: 1193 | F19: 2699 | G19: 6310
A20: Accrued and other current liabilities | B20: 1097 | C20: 1725 | D20: 2552 | E20: 4120 | F20: 6682 | G20: 11737
A21: Short-term debt | B21: 0 | C21: 999 | D21: 0 | E21: 1250 | F21: 1250 | G21: 0
A22: Total current liabilities | B22: 1784 | C22: 3925 | D22: 4335 | E22: 6563 | F22: 10631 | G22: 18047
A23: Long-term debt | B23: 1991 | C23: 5964 | D23: 10946 | E23: 9703 | F23: 8459 | G23: 8463
A24: Long-term operating lease liabilities | B24: 561 | C24: 634 | D24: 741 | E24: 902 | F24: 1119 | G24: 1519
A25: Other long-term liabilities | B25: 775 | C25: 1375 | D25: 1553 | E25: 1913 | F25: 2541 | G25: 4245
A26: Total liabilities | B26: 5111 | C26: 11898 | D26: 17575 | E26: 19081 | F26: 22750 | G26: 32274
A27: Shareholders' equity:
A28: Preferred stock, $0.001 par value; authorized, none issued | C28: — | D28: — | E28: — | F28: — | G28: —
A29: Common stock, $0.001 par value | B29: 1 | C29: 1 | D29: 3 | E29: 2 | F29: 25 | G29: 24
A30: Additional paid-in capital | B30: 7045 | C30: 8721 | D30: 10385 | E30: 11971 | F30: 13109 | G30: 11237
A31: Treasury Stock | B31: -9814 | C31: -10756 | D31: 0 | E31: 0 | F31: 0 | G31: 0
A32: Accumulated other comprehensive income (loss) | B32: 1 | C32: 19 | D32: -11 | E32: -43 | F32: 27 | G32: 28
A33: Retained earnings | B33: 14971 | C33: 18908 | D33: 16235 | E33: 10171 | F33: 29817 | G33: 68038
A34: Total shareholders' equity | B34: 12204 | C34: 16893 | D34: 26612 | E34: 22101 | F34: 42978 | G34: 79327
A35: Total liabilities and shareholders' equity | B35: 17315 | C35: 28791 | D35: 44187 | E35: 41182 | F35: 65728 | G35: 111601

Sheet Raw Cash Flow
A1: Years ended | B1: Jan 26, 2020 | C1: Jan 31, 2021 | D1: Jan 30, 2022 | E1: Jan 29, 2023 | F1: Jan 28, 2024 | G1: Jan 26, 2025
A2: Cash flows from operating activities:
A3: Net income | B3: 2796 | C3: 4332 | D3: 9752 | E3: 4368 | F3: 29760 | G3: 72880
A4: Stock‑based compensation expense | B4: 844 | C4: 1397 | D4: 2004 | E4: 2709 | F4: 3549 | G4: 4737
A5: Depreciation and amortization | B5: 381 | C5: 1098 | D5: 1174 | E5: 1544 | F5: 1508 | G5: 1864
A6: Deferred income taxes | B6: 18 | C6: -282 | D6: -406 | E6: -2164 | F6: -2489 | G6: -4477
A7: (Gains) losses on non‑marketable equity securities and publicly‑held equity securities, net | B7: 1 | C7: 0 | D7: -100 | E7: 45 | F7: -238 | G7: -1030
A8: Acquisition termination cost | B8: 0 | C8: 0 | D8: 0 | E8: 1353 | F8: 0 | G8: 0
A9: Other | B9: 4 | C9: -20 | D9: 47 | E9: -7 | F9: -278 | G9: -502
A10: Changes in operating assets and liabilities, net of acquisitions:
A11: Accounts receivable | B11: -233 | C11: -550 | D11: -2215 | E11: 822 | F11: -6172 | G11: -13063
A12: Inventories | B12: 597 | C12: -524 | D12: -774 | E12: -2554 | F12: -98 | G12: -4781
A13: Prepaid expenses and other assets | B13: 77 | C13: -394 | D13: -1715 | E13: -1517 | F13: -1522 | G13: -395
A14: Accounts payable | B14: 194 | C14: 312 | D14: 568 | E14: -551 | F14: 1531 | G14: 3357
A15: Accrued and other current liabilities | B15: 54 | C15: 290 | D15: 581 | E15: 1341 | F15: 2025 | G15: 4278
A16: Other long‑term liabilities | B16: 27 | C16: 163 | D16: 192 | E16: 252 | F16: 514 | G16: 1221
A17: Net cash provided by operating activities | B17: 4761 | C17: 5822 | D17: 9108 | E17: 5641 | F17: 28090 | G17: 64089
A18: Cash flows from investing activities:
A19: Proceeds from maturities of marketable securities | B19: 4744 | C19: 8792 | D19: 15197 | E19: 19425 | F19: 9732 | G19: 11195
A20: Proceeds from sales of marketable securities | B20: 3365 | C20: 527 | D20: 1023 | E20: 1806 | F20: 50 | G20: 495
A21: Proceeds from sales of non‑marketable equity securities | B21: 0 | C21: 0 | D21: 0 | E21: 8 | F21: 1 | G21: 171
A22: Purchases of marketable securities | B22: -1461 | C22: -19308 | D22: -24787 | E22: -11897 | F22: -18211 | G22: -26575
A23: Purchases related to property and equipment and intangible assets | B23: -489 | C23: -1128 | D23: -976 | E23: -1833 | F23: -1069 | G23: -3236
A24: Purchases of non‑marketable equity securities | B24: 0 | C24: 0 | D24: 0 | E24: -85 | F24: -862 | G24: -1486
A25: Acquisitions, net of cash acquired | B25: -4 | C25: -8524 | D25: -263 | E25: -49 | F25: -83 | G25: -1007
A26: Other | B26: -10 | C26: -34 | D26: -24 | E26: 0 | F26: -124 | G26: 22
A27: Net cash provided by (used in) investing activities | B27: 6145 | C27: -19675 | D27: -9830 | E27: 7375 | F27: -10566 | G27: -20421
A28: Cash flows from financing activities:
A29: Issuance of debt, net issuance costs | B29: 0 | C29: 4968 | D29: 4977 | E29: 0 | F29: 0 | G29: 0
A30: Proceeds related to employee stock plans | B30: 149 | C30: 194 | D30: 281 | E30: 355 | F30: 403 | G30: 490
A31: Payments related to repurchases of common stock | B31: 0 | C31: 0 | D31: 0 | E31: -10039 | F31: -9533 | G31: -33706
A32: Payments related to tax on restricted stock units | B32: -551 | C32: -942 | D32: -1904 | E32: -1475 | F32: -2783 | G32: -6930
A33: Repayment of debt | B33: 0 | C33: 0 | D33: -1000 | E33: 0 | F33: -1250 | G33: -1250
A34: Dividends paid | B34: -390 | C34: -395 | D34: -399 | E34: -398 | F34: -395 | G34: -834
A35: Principal payments on property and equipment and intangible assets | B35: 0 | C35: -17 | D35: -83 | E35: -58 | F35: -74 | G35: -129
A36: Other | B36: 0 | C36: -4 | D36: -7 | E36: -2 | F36: -1 | G36: 0
A37: Net cash used in financing activities | B37: -792 | C37: 3804 | D37: 1865 | E37: -11617 | F37: -13633 | G37: -42359
A38: Change in cash and cash equivalents | B38: 10114 | C38: -10049 | D38: 1143 | E38: 1399 | F38: 3891 | G38: 1309
A39: Cash and cash equivalents at beginning of period | B39: 782 | C39: 10896 | D39: 847 | E39: 1990 | F39: 3389 | G39: 7280
A40: Cash and cash equivalents at end of period | B40: 10896 | C40: 847 | D40: 1990 | E40: 3389 | F40: 7280 | G40: 8589
...

Sheet Financial Model & Forecast
C1: Historical Results | H1: Forecast Period
C2: 2021 | D2: 2022 | E2: 2023 | F2: 2024 | G2: 2025 | H2: 2026 | I2: 2027 | J2: 2028 | K2: 2029 | L2: 2030
A3: Balance Sheet Check | C3: =IFERROR(IF(ABS(C76)>1,"ERROR","OK"),"OK") -> OK | D3: =IFERROR(IF(ABS(D76)>1,"ERROR","OK"),"OK") -> OK | E3: =IFERROR(IF(ABS(E76)>1,"ERROR","OK"),"OK") -> OK | F3: =IFERROR(IF(ABS(F76)>1,"ERROR","OK"),"OK") -> OK | G3: =IFERROR(IF(ABS(G76)>1,"ERROR","OK"),"OK") -> OK | H3: =IFERROR(IF(ABS(H76)>1,"ERROR","OK"),"OK") -> OK | I3: =IFERROR(IF(ABS(I76)>1,"ERROR","OK"),"OK") -> OK | J3: =IFERROR(IF(ABS(J76)>1,"ERROR","OK"),"OK") -> OK | ... L3: =IFERROR(IF(ABS(L76)>1,"ERROR","OK"),"OK") -> OK
A6: Assumptions | C6: 2021 | D6: 2022 | E6: 2023 | F6: 2024 | G6: 2025 | H6: 2026 | I6: 2027 | J6: 2028 | K6: 2029 | L6: 2030
A9: Key Assumptions
A10: Revenue Growth (% Change) | D10: =D34/C34-1 -> 0.61403298 | E10: =E34/D34-1 -> 0.002229323 | F10: =F34/E34-1 -> 1.2585453 | G10: =G34/F34-1 -> 1.1420341 | H10: 0.6 | I10: 0.3 | J10: 0.18 | K10: 0.12 | L10: 0.1
A11: Gross Margin (%) | C11: =C36/C34 -> 0.62344828 | D11: =D36/D34 -> 0.64929033 | E11: =E36/E34 -> 0.56928894 | F11: =F36/F34 -> 0.72717573 | G11: =G36/G34 -> 0.74988697 | H11: 0.74 | I11: 0.72 | J11: 0.7 | K11: 0.68 | L11: 0.68
A12: SG&A (% of Revenue) | C12: =C38/C34 -> 0.11634183 | D12: =D38/D34 -> 0.080478561 | E12: =E38/E34 -> 0.090457478 | F12: =F38/F34 -> 0.043563901 | G12: =G38/G34 -> 0.026751573 | H12: 0.04 | I12: 0.05 | J12: 0.06 | K12: 0.07 | L12: 0.07
A13: Research and Development (% of Revenue) | C13: =C37/C34 -> 0.23532234 | D13: =D37/D34 -> 0.19573456 | E13: =E37/E34 -> 0.27207681 | F13: =F37/F34 -> 0.14239519 | G13: =G37/G34 -> 0.098960129 | H13: 0.11 | I13: 0.13 | J13: 0.15 | K13: 0.15 | L13: 0.17
A14: Other/One-off Opex | C14: =C39 -> 0 | D14: =D39 -> 0 | E14: =E39 -> 1353 | F14: =F39 -> 0 | G14: =G39 -> 0 | H14: 0 | I14: 0 | J14: 0 | K14: 0 | L14: 0
A15: Accounts Receivable (Days) | C15: =C57/C34*C28 -> 53.168516 | D15: =D57/D34*D28 -> 63.061975 | E15: =E57/E34*E28 -> 51.785238 | F15: =F57/F34*F28 -> 59.906684 | G15: =G57/G34*G28 -> 64.512786 | H15: 62 | I15: 62 | J15: 63 | K15: 63 | L15: 63
A16: Inventory (Days) | C16: =C58/C35*C28 -> 106.14588 | D16: =D58/D35*D28 -> 100.73366 | E16: =E58/E35*E28 -> 162.0791 | F16: =F58/F35*F28 -> 115.99362 | G16: =G58/G35*G28 -> 112.72404 | H16: 110 | I16: 108 | J16: 105 | K16: 103 | L16: 100
A17: Accounts Payable (Days) | C17: =C64/C35*C28 -> 69.814461 | D17: =D64/D35*D28 -> 68.947452 | E17: =E64/E35*E28 -> 37.480203 | F17: =F64/F35*F28 -> 59.270501 | G17: =G64/G35*G28 -> 70.564356 | H17: 68 | I17: 68 | J17: 67 | K17: 67 | L17: 67
A18: Capex (% of Revenue) | C18: =-C96/C34 -> 0.067646177 | D18: =-D96/D34 -> 0.036263655 | E18: =-E96/E34 -> 0.067954326 | F18: =-F96/F34 -> 0.017547027 | G18: =-G96/G34 -> 0.024797505 | H18: 0.035 | I18: 0.04 | J18: 0.04 | K18: 0.042 | L18: 0.045
A19: D&A (% of PPE) | C19: =C83/C59 -> 0.51093532 | D19: =D83/D59 -> 0.42260619 | E19: =E83/E59 -> 0.40556869 | F19: =F83/F59 -> 0.3852836 | G19: =G83/G59 -> 0.29667356 | H19: 0.32 | I19: 0.32 | J19: 0.31 | K19: 0.3 | L19: 0.3
A20: Stock-Based Comp % Revenue | C20: =C84/C34 -> 0.083778111 | D20: =D84/D34 -> 0.074459389 | E20: =E84/E34 -> 0.10043004 | F20: =F84/F34 -> 0.058254818 | G20: =G84/G34 -> 0.036299685 | H20: 0.04 | I20: 0.038 | J20: 0.035 | K20: 0.033 | L20: 0.03
A21: Effective Tax Rate (%) | C21: =C45/C44 -> 0.017464278 | D21: =D45/D44 -> 0.019012172 | E21: =E45/E44 -> -0.044726142 | F21: =F45/F44 -> 0.11999527 | G21: =G45/G44 -> 0.13264942 | H21: 0.14 | I21: 0.15 | J21: 0.16 | K21: 0.16 | L21: 0.17
A22: Interest on Cash (%) | C22: =C130/C114 -> 0.0052312775 | D22: =D130/D114 -> 0.034238489 | E22: =E130/E114 -> 0.13417085 | F22: =F130/F114 -> 0.25553261 | G22: =G130/G114 -> 0.24532967 | H22: 0.2 | I22: 0.13 | J22: 0.12 | K22: 0.11 | L22: 0.1
A23: Interest on Debt (%) | C23: =-C131/C126 -> 0.092415871 | D23: =-D131/D126 -> 0.033893437 | E23: =-E131/E126 -> 0.023935684 | F23: =-F131/F126 -> 0.023463891 | G23: =-G131/G126 -> 0.025440313 | H23: 0.03 | I23: 0.03 | J23: 0.03 | K23: 0.03 | L23: 0.03
A24: Buyback Ratio (% of Net Income) | C24: =C106/-C46 -> 0 | D24: =D106/-D46 -> 0 | E24: =E106/-E46 -> 2.2983059 | F24: =F106/-F46 -> 0.3203293 | G24: =G106/-G46 -> 0.46248628 | H24: 0.5 | I24: 0.5 | J24: 0.5 | K24: 0.5 | L24: 0.5
A25: Dividend Payout Ratio | C25: =-C107/C46 -> 0.091181902 | D25: =-D107/D46 -> 0.040914684 | E25: =-E107/E46 -> 0.091117216 | F25: =-F107/F46 -> 0.013272849 | G25: =-G107/G46 -> 0.011443469 | H25: 0.02 | I25: 0.02 | J25: 0.03 | K25: 0.04 | L25: 0.04
A26: Accured Liability (% of Opex) | C26: =C66/C40 -> 0.2941678 | D26: =D66/D40 -> 0.3432876 | E26: =E66/E40 -> 0.3701042 | F26: =F66/F40 -> 0.58981375 | G26: =G66/G40 -> 0.71545261 | H26: 0.7 | I26: 0.65 | J26: 0.6 | K26: 0.6 | L26: 0.6
A27: Debt Issuance (Repayment) | C27: =C104+C105 -> 4968 | D27: =D104+D105 -> 3977 | E27: =E104+E105 -> 0 | F27: =F104+F105 -> -1250 | G27: =G104+G105 -> -1250 | H27: -2000 | I27: -2000 | J27: -1000 | K27: -1000 | L27: -1000
A28: Days in Period | C28: 365 | D28: 365 | E28: 365 | F28: 365 | G28: 365 | H28: 365 | I28: 365 | J28: 365 | K28: 365 | L28: 365
A31: Income Statement | C31: 2021 | D31: 2022 | E31: 2023 | F31: 2024 | G31: 2025 | H31: 2026 | I31: 2027 | J31: 2028 | K31: 2029 | L31: 2030
A34: Net Revenue | C34: ='Raw P&L'!B2 -> 16675 | D34: ='Raw P&L'!C2 -> 26914 | E34: ='Raw P&L'!D2 -> 26974 | F34: ='Raw P&L'!E2 -> 60922 | G34: ='Raw P&L'!F2 -> 130497 | H34: =G34*(1+H10) -> 208795.2 | I34: =H34*(1+I10) -> 271433.76 | J34: =I34*(1+J10) -> 320291.84 | K34: =J34*(1+K10) -> 358726.86 | L34: =K34*(1+L10) -> 394599.54
A35: Cost of Revenue | C35: ='Raw P&L'!B3 -> 6279 | D35: ='Raw P&L'!C3 -> 9439 | E35: ='Raw P&L'!D3 -> 11618 | F35: ='Raw P&L'!E3 -> 16621 | G35: ='Raw P&L'!F3 -> 32639 | H35: =H34*(1-H11) -> 54286.752 | I35: =I34*(1-I11) -> 76001.453 | J35: =J34*(1-J11) -> 96087.551 | K35: =K34*(1-K11) -> 114792.59 | L35: =L34*(1-L11) -> 126271.85
A36: Gross Profit | C36: =C34-C35 -> 10396 | D36: =D34-D35 -> 17475 | E36: =E34-E35 -> 15356 | F36: =F34-F35 -> 44301 | G36: =G34-G35 -> 97858 | H36: =H34-H35 -> 154508.45 | I36: =I34-I35 -> 195432.31 | J36: =J34-J35 -> 224204.29 | ... L36: =L34-L35 -> 268327.69
A37: Research & Development | C37: ='Raw P&L'!B6 -> 3924 | D37: ='Raw P&L'!C6 -> 5268 | E37: ='Raw P&L'!D6 -> 7339 | F37: ='Raw P&L'!E6 -> 8675 | G37: ='Raw P&L'!F6 -> 12914 | H37: =H34*H13 -> 22967.472 | I37: =I34*I13 -> 35286.389 | J37: =J34*J13 -> 48043.776 | K37: =K34*K13 -> 53809.029 | L37: =L34*L13 -> 67081.922
A38: SG&A | C38: ='Raw P&L'!B7 -> 1940 | D38: ='Raw P&L'!C7 -> 2166 | E38: ='Raw P&L'!D7 -> 2440 | F38: ='Raw P&L'!E7 -> 2654 | G38: ='Raw P&L'!F7 -> 3491 | H38: =H34*H12 -> 8351.808 | I38: =I34*I12 -> 13571.688 | J38: =J34*J12 -> 19217.51 | K38: =K34*K12 -> 25110.88 | L38: =L34*L12 -> 27621.968
A39: Other Operating Expenses (Acquisition termination cost ) | C39: ='Raw P&L'!B8 -> 0 | D39: ='Raw P&L'!C8 -> 0 | E39: ='Raw P&L'!D8 -> 1353 | F39: ='Raw P&L'!E8 -> 0 | G39: ='Raw P&L'!F8 -> 0 | H39: =H14 -> 0 | I39: =I14 -> 0 | J39: =J14 -> 0 | K39: =K14 -> 0 | L39: =L14 -> 0
A40: Total Operating Expenses | C40: =SUM(C37:C39) -> 5864 | D40: =SUM(D37:D39) -> 7434 | E40: =SUM(E37:E39) -> 11132 | F40: =SUM(F37:F39) -> 11329 | G40: =SUM(G37:G39) -> 16405 | H40: =SUM(H37:H39) -> 31319.28 | I40: =SUM(I37:I39) -> 48858.077 | J40: =SUM(J37:J39) -> 67261.286 | ... L40: =SUM(L37:L39) -> 94703.89
A41: EBIT (Operating Income) | C41: =C36-C40 -> 4532 | D41: =D36-D40 -> 10041 | E41: =E36-E40 -> 4224 | F41: =F36-F40 -> 32972 | G41: =G36-G40 -> 81453 | H41: =H36-H40 -> 123189.17 | I41: =I36-I40 -> 146574.23 | J41: =J36-J40 -> 156943 | ... L41: =L36-L40 -> 173623.8
A42: Interest (Net) | C42: =C132 -> -127 | D42: =D132 -> -207 | E42: =E132 -> 5 | F42: =F132 -> 609 | G42: =G132 -> 1539 | H42: =H132 -> 1463.91 | I42: =I132 -> 2628.9417 | J42: =J132 -> 4283.1964 | ... L42: =L132 -> 6137.1589
A43: Other Income (Net) | C43: ='Raw P&L'!B13 -> 4 | D43: ='Raw P&L'!C13 -> 107 | E43: ='Raw P&L'!D13 -> -48 | F43: ='Raw P&L'!E13 -> 237 | G43: ='Raw P&L'!F13 -> 1034 | H43: 300 | I43: 300 | J43: 300 | K43: 300 | L43: 300
A44: EBT (Income Before Tax) | C44: =SUM(C41:C43) -> 4409 | D44: =SUM(D41:D43) -> 9941 | E44: =SUM(E41:E43) -> 4181 | F44: =SUM(F41:F43) -> 33818 | G44: =SUM(G41:G43) -> 84026 | H44: =SUM(H41:H43) -> 124953.08 | I44: =SUM(I41:I43) -> 149503.17 | J44: =SUM(J41:J43) -> 161526.2 | ... L44: =SUM(L41:L43) -> 180060.96
A45: Income Tax Expense | C45: ='Raw P&L'!B16 -> 77 | D45: ='Raw P&L'!C16 -> 189 | E45: ='Raw P&L'!D16 -> -187 | F45: ='Raw P&L'!E16 -> 4058 | G45: ='Raw P&L'!F16 -> 11146 | H45: =H44*H21 -> 17493.431 | I45: =I44*I21 -> 22425.476 | J45: =J44*J21 -> 25844.191 | K45: =K44*K21 -> 27319.617 | L45: =L44*L21 -> 30610.363
A46: Net Income | C46: =C44-C45 -> 4332 | D46: =D44-D45 -> 9752 | E46: =E44-E45 -> 4368 | F46: =F44-F45 -> 29760 | G46: =G44-G45 -> 72880 | H46: =H44-H45 -> 107459.65 | I46: =I44-I45 -> 127077.7 | J46: =J44-J45 -> 135682 | ... L46: =L44-L45 -> 149450.6
A48: Model Helper (Cross - Statement) D&A (from CF) | C48: ='Raw Cash Flow'!C5 -> 1098 | D48: ='Raw Cash Flow'!D5 -> 1174 | E48: ='Raw Cash Flow'!E5 -> 1544 | F48: ='Raw Cash Flow'!F5 -> 1508 | G48: ='Raw Cash Flow'!G5 -> 1864 | H48: =H83 -> 2010.56 | I48: =I83 -> 3705.687 | J48: =J83 -> 5806.9 | K48: =K83 -> 7721.0127 | L48: =L83 -> 9924.6673
A49: EBITDA | C49: =C41+C48 -> 5630 | D49: =D41+D48 -> 11215 | E49: =E41+E48 -> 5768 | F49: =F41+F48 -> 34480 | G49: =G41+G48 -> 83317 | H49: =H41+H48 -> 125199.73 | I49: =I41+I48 -> 150279.92 | J49: =J41+J48 -> 162749.9 | ... L49: =L41+L48 -> 183548.47
...

Sheet Historical Statements Mapping
A1: Raw Statement | B1: Raw Line Item | C1: Model Statement | D1: Model Line Item
A2: Income Statement | B2: Revenue | C2: Income Statement | D2: Net Revenue
A3: Income Statement | B3: Cost of revenue | C3: Income Statement | D3: Cost of Revenue
A4: Income Statement | B4: Gross profit | C4: Income Statement | D4: Gross Profit
A5: Income Statement | B5: Research and development | C5: Income Statement | D5: Research & Development
A6: Income Statement | B6: Sales, general and administrative | C6: Income Statement | D6: SG&A
A7: Income Statement | B7: Acquisition termination cost | C7: Income Statement | D7: Other Operating Expenses
A8: Income Statement | B8: Total operating expenses | C8: Income Statement | D8: Total Operating Expenses
A9: Income Statement | B9: Operating income / income from operations | C9: Income Statement | D9: EBIT (Operating Income)
A10: Income Statement | B10: Interest income | C10: Income Statement | D10: Interest (Net)
A11: Income Statement | B11: Interest expense | C11: Income Statement | D11: Interest (Net)
A12: Income Statement | B12: Other, net | C12: Income Statement | D12: Other Income (Net)
... A66: Cash Flow | B66: Other | C66: Cash Flow | D66: Other Financing Activities

Sheet Forecast Statement Formulas
A1: Statement | B1: Line Item | C1: Driver & Calculation
A2: Income Statement | B2: Net Revenue | C2: Revenue_(t-1) * (1 + Revenue Growth)
A3: Income Statement | B3: Cost of Revenue | C3: Revenue * (1 - Gross Margin)
A4: Income Statement | B4: Gross Profit | C4: Net Revenue - Cost of Revenue
A5: Income Statement | B5: Research & Development | C5: Revenue * R&D % of Revenue
A6: Income Statement | B6: SG&A | C6: Revenue * SG&A % of Revenue
A7: Income Statement | B7: Other Operating Expenses | C7: Assumption: Other / One-off Opex
A8: Income Statement | B8: Total Operating Expenses | C8: R&D + SG&A + Other OpEx
A9: Income Statement | B9: EBIT (Operating Income) | C9: Gross Profit - Total Operating Expenses
A10: Income Statement | B10: Interest (Net) | C10: Interest Income - Interest Expense
A11: Income Statement | B11: EBT (Income Before Tax) | C11: EBIT + Interest (Net)
A12: Income Statement | B12: Income Tax Expense | C12: EBT * Effective Tax Rate
... A60: Cash Flow | B60: Closing Cash Balance | C60: Opening Cash + Net Change in Cash

Sheet Assumptions Formulas
A1: Assumption Item | B1: Definition and Correct Application in This Model
A2: Revenue Growth (% Change) | B2: Revenue_t = Revenue_(t-1) * (1 + Revenue Growth)
A3: Gross Margin (%) | B3: Gross Margin = Gross Profit / Revenue → Gross Profit_t = Revenue_t * Gross Margin; Cost of Revenue_t = Revenue_t - Gross Profit_t
A4: SG&A (% of Revenue) | B4: SG&A % = SG&A / Revenue → SG&A_t = Revenue_t * SG&A %
A5: Research and Development (% of Revenue) | B5: R&D % = R&D / Revenue → R&D_t = Revenue_t * R&D %
A6: Other / One-off Opex | B6: Direct input for non-recurring operating expenses
A7: Accounts Receivable (Days) | B7: AR Days = Accounts Receivable / Revenue * Days → Accounts Receivable_t = Revenue_t / Days in Period * AR Days
A8: Inventory (Days) | B8: Inventory Days = Inventory / Cost of Revenue * Days → Inventory_t = Cost of Revenue_t / Days in Period * Inventory Days
A9: Accounts Payable (Days) | B9: AP Days = Accounts Payable / Cost of Revenue * Days → Accounts Payable_t = Cost of Revenue_t / Days in Period * AP Days
A10: Capex (% of Revenue) | B10: Capex % = Capex / Revenue → Capex_t = Revenue_t * Capex %
A11: D&A (% of PPE) | B11: D&A % = Depreciation / PPE → Depreciation_t = PPE_(t-1) * D&A %
A12: Stock-Based Comp (% of Revenue) | B12: SBC % = SBC / Revenue → SBC_t = Revenue_t * SBC %
... A20: Days in Period | B20: Number of days used in working capital calculations (365 for annual model)
