Workbook

Sheet SKILLFIN LEARNING

Sheet Historical IS and BS
A1: WAL-MART STORES, INC.
A2: Historical standardized financial statements - Income statement and Balance sheet
A3: U$ bn
B5: Income Statement | C5: 2012A | D5: 2013A | E5: 2014A | F5: 2015A | G5: 2016A | H5: 2017A
B6: Revenues | C6: =446.509 -> 446.509 | D6: =468.651 -> 468.651 | E6: 476.294 | F6: 485.651 | G6: 482.13 | H6: 485.873
B7: Cost of goods sold (excluding depreciation and amortization cost) | C7: =334.993-8.106 -> 326.887 | D7: =352.297-8.478 -> 343.819 | E7: =358.069-8.87 -> 349.199 | F7: =365.086-9.173 -> 355.913 | G7: =360.984-9.454 -> 351.53 | H7: =361.256-H10 -> 351.176
B8: Gross profit | C8: =C6-C7 -> 119.622 | D8: =D6-D7 -> 124.832 | E8: =E6-E7 -> 127.095 | F8: =F6-F7 -> 129.738 | G8: =G6-G7 -> 130.6 | H8: =H6-H7 -> 134.697 | K8: s
B9: SG&A expenses | C9: =85.025 -> 85.025 | D9: =88.629 -> 88.629 | E9: 91.353 | F9: 93.418 | G9: =97.041 -> 97.041 | H9: =101.853 -> 101.853
B10: Depreciation and Amortization cost | C10: =8.106 -> 8.106 | D10: =8.478 -> 8.478 | E10: 8.87 | F10: 9.173 | G10: 9.454 | H10: 10.08
B11: EBIT | C11: =C8-C9-C10 -> 26.491 | D11: =D8-D9-D10 -> 27.725 | E11: =E8-E9-E10 -> 26.872 | F11: =F8-F9-F10 -> 27.147 | G11: =G8-G9-G10 -> 24.105 | H11: =H8-H9-H10 -> 22.764
B12: Interest expense (net of interest income) | C12: =2.159 -> 2.159 | D12: =2.063 -> 2.063 | E12: 2.216 | F12: 2.348 | G12: =2.467 -> 2.467 | H12: =2.267 -> 2.267
B13: EBT | C13: =C11-C12 -> 24.332 | D13: =D11-D12 -> 25.662 | E13: =E11-E12 -> 24.656 | F13: =F11-F12 -> 24.799 | G13: =G11-G12 -> 21.638 | H13: =H11-H12 -> 20.497
B14: Provisions for taxes | C14: =7.924 -> 7.924 | D14: =7.958 -> 7.958 | E14: 8.105 | F14: 7.985 | G14: =6.558 -> 6.558 | H14: 6.204
B15: Profits after tax (continuing operations) | C15: =C13-C14 -> 16.408 | D15: =D13-D14 -> 17.704 | E15: =E13-E14 -> 16.551 | F15: =F13-F14 -> 16.814 | G15: =G13-G14 -> 15.08 | H15: =H13-H14 -> 14.293
B16: Income from discontinued operations (net of taxes) | C16: -0.021 | D16: 0.052 | E16: 0.144 | F16: 0.285 | G16: 0 | H16: 0
B17: Consolidated net income | C17: =C15+C16 -> 16.387 | D17: =D15+D16 -> 17.756 | E17: =E15+E16 -> 16.695 | F17: =F15+F16 -> 17.099 | G17: =G15+G16 -> 15.08 | H17: =H15+H16 -> 14.293
B18: Minority interest share of profits | C18: 0.688 | D18: 0.757 | E18: 0.673 | F18: 0.736 | G18: 0.386 | H18: 0.65
B19: Consolidated net income attributable to Walmart | C19: =C17-C18 -> 15.699 | D19: =D17-D18 -> 16.999 | E19: =E17-E18 -> 16.022 | F19: =F17-F18 -> 16.363 | G19: =G17-G18 -> 14.694 | H19: =H17-H18 -> 13.643
B21: Balance Sheet - Assets | C21: =C5 -> 2012A | D21: =D5 -> 2013A | E21: =E5 -> 2014A | F21: =F5 -> 2015A | G21: =G5 -> 2016A | H21: =H5 -> 2017A
B22: Cash | C22: =6.55 -> 6.55 | D22: =7.781 -> 7.781 | E22: =7.281 -> 7.281 | F22: 9.135 | G22: 8.705 | H22: 6.867
B23: Accounts Receivables | C23: =5.937 -> 5.937 | D23: =6.768 -> 6.768 | E23: =6.677 -> 6.677 | F23: =6.778 -> 6.778 | G23: 5.624 | H23: 5.835
B24: Inventory | C24: =40.714 -> 40.714 | D24: =43.803 -> 43.803 | E24: =44.858 -> 44.858 | F24: 45.141 | G24: 44.469 | H24: 43.046
B25: Other current assets | C25: 1.685 | D25: 1.551 | E25: 1.909 | F25: 2.224 | G25: 1.441 | H25: 1.941
B26: Current assets of discontinued operations | C26: 0.089 | D26: 0.037 | E26: 0.46 | F26: 0 | G26: 0 | H26: 0
B27: Total current assets | C27: =SUM(C22:C26) -> 54.975 | D27: =SUM(D22:D26) -> 59.94 | E27: =SUM(E22:E26) -> 61.185 | F27: =SUM(F22:F26) -> 63.278 | G27: =SUM(G22:G26) -> 60.239 | H27: =SUM(H22:H26) -> 57.689
B29: Plant and Machinery | C29: =109.603+2.721 -> 112.324 | D29: =113.929+2.752 -> 116.681 | E29: =115.364+2.543 -> 117.907 | F29: =114.28+2.375 -> 116.655 | G29: =110.171+6.345 -> 116.516 | H29: =107.71+6.468 -> 114.178
B30: Goodwill | C30: =20.651 -> 20.651 | D30: =20.497 -> 20.497 | E30: =19.51 -> 19.51 | F30: =18.102 -> 18.102 | G30: =16.695 -> 16.695 | H30: 17.037
B31: Other long term assets | C31: =5.456 -> 5.456 | D31: =5.987 -> 5.987 | E31: =6.149 -> 6.149 | F31: =5.455 -> 5.455 | G31: =6.131 -> 6.131 | H31: 9.921
B32: Total assets | C32: =C27+C29+C31+C30 -> 193.406 | D32: =D27+D29+D31+D30 -> 203.105 | E32: =E27+E29+E31+E30 -> 204.751 | F32: =F27+F29+F31+F30 -> 203.49 | G32: =G27+G29+G31+G30 -> 199.581 | H32: =H27+H29+H31+H30 -> 198.825
B34: Balance Sheet - Liabilities and equity | C34: =C21 -> 2012A | D34: =D21 -> 2013A | E34: =E21 -> 2014A | F34: =F21 -> 2015A | G34: =G21 -> 2016A | H34: =H21 -> 2017A
B35: Short term debt | C35: =4.047+1.975+0.326 -> 6.348 | D35: =6.805+5.587+0.327 -> 12.719 | E35: =7.67+4.103+0.309 -> 12.082 | F35: =1.592+4.791+0.287 -> 6.67 | G35: =2.708+2.745+0.551 -> 6.004 | H35: =1.099+2.256+0.565 -> 3.92
B36: Accounts payable | C36: =36.608 -> 36.608 | D36: =38.08 -> 38.08 | E36: =37.415 -> 37.415 | F36: 38.41 | G36: 38.487 | H36: 41.433
B37: Other short term liabilities | C37: =18.154+1.164+0.026 -> 19.344 | D37: =18.808+2.211 -> 21.019 | E37: =18.793+0.966+0.089 -> 19.848 | F37: =19.152+1.021 -> 20.173 | G37: =19.607+0.521 -> 20.128 | H37: =20.654+0.921 -> 21.575
B38: Total current liabilities | C38: =SUM(C35:C37) -> 62.3 | D38: =SUM(D35:D37) -> 71.818 | E38: =SUM(E35:E37) -> 69.345 | F38: =SUM(F35:F37) -> 65.253 | G38: =SUM(G35:G37) -> 64.619 | H38: =SUM(H35:H37) -> 66.928
B40: Long term debt | C40: =44.07+3.009 -> 47.079 | D40: =38.394+3.023 -> 41.417 | E40: =41.771+2.788 -> 44.559 | F40: =40.889+2.606 -> 43.495 | G40: =38.214+5.816 -> 44.03 | H40: =36.015+6.003 -> 42.018
B41: Other long term liabilities | C41: =7.862+0.404 -> 8.266 | D41: =7.613+0.519 -> 8.132 | E41: =8.017+1.491 -> 9.508 | F41: =8.805 -> 8.805 | G41: =7.321 -> 7.321 | H41: 9.344
B43: Minority interest | C43: 4.446 | D43: 5.395 | E43: 5.084 | F43: 4.543 | G43: 3.065 | H43: 2.737
B44: Common equity | C44: 71.315 | D44: =76.343 -> 76.343 | E44: 76.255 | F44: 81.394 | G44: 80.546 | H44: 77.798
B45: Total liabilities and equity | C45: =C44+C40+C41+C38+C43 -> 193.406 | D45: =D44+D40+D41+D38+D43 -> 203.105 | E45: =E44+E40+E41+E38+E43 -> 204.751 | F45: =F44+F40+F41+F38+F43 -> 203.49 | G45: =G44+G40+G41+G38+G43 -> 199.581 | H45: =H44+H40+H41+H38+H43 -> 198.825
B46: Check | C46: =C45=C32 -> TRUE | D46: =D45=D32 -> TRUE | E46: =E45=E32 -> TRUE | F46: =F45=F32 -> TRUE | G46: =G45=G32 -> TRUE | H46: =H45=H32 -> TRUE

Sheet Key ratios
A1: WAL-MART STORES, INC.
A2: Key income statement and balance sheet ratios
A3: Percent, USD bn
D4: HISTORICAL | I4: FORECASTED
B5: Income Statement ratios | C5: Unit | D5: 2013A | E5: 2014A | F5: 2015A | G5: 2016A | H5: 2017A | I5: 2018E | J5: 2019E | K5: 2020E | L5: 2021E | M5: 2022E
B6: Year on year revenue growth | C6: % | D6: ='Historical IS and BS'!D6/'Historical IS and BS'!C6-1 -> 0.049589146 | E6: ='Historical IS and BS'!E6/'Historical IS and BS'!D6-1 -> 0.016308511 | F6: ='Historical IS and BS'!F6/'Historical IS and BS'!E6-1 -> 0.019645429 | G6: ='Historical IS and BS'!G6/'Historical IS and BS'!F6-1 -> -0.0072500623 | H6: ='Historical IS and BS'!H6/'Historical IS and BS'!G6-1 -> 0.0077634663 | I6: =H6+0.2% -> 0.0097634663 | J6: =I6+0.2% -> 0.011763466 | K6: =J6+0.2% -> 0.013763466 | L6: =K6+0.2% -> 0.015763466 | M6: =L6+0.2% -> 0.017763466
B7: Cost of goods sold as % of revenues | C7: % | D7: ='Historical IS and BS'!D7/'Historical IS and BS'!D6 -> 0.73363548 | E7: ='Historical IS and BS'!E7/'Historical IS and BS'!E6 -> 0.73315851 | F7: ='Historical IS and BS'!F7/'Historical IS and BS'!F6 -> 0.73285755 | G7: ='Historical IS and BS'!G7/'Historical IS and BS'!G6 -> 0.7291187 | H7: ='Historical IS and BS'!H7/'Historical IS and BS'!H6 -> 0.72277323 | I7: =H7-0.2% -> 0.72077323 | J7: =I7-0.2% -> 0.71877323 | K7: =J7-0.2% -> 0.71677323 | L7: =K7-0.2% -> 0.71477323 | M7: =L7-0.2% -> 0.71277323
B8: SG&A expenses as % revenues | C8: % | D8: ='Historical IS and BS'!D9/'Historical IS and BS'!D6 -> 0.18911514 | E8: ='Historical IS and BS'!E9/'Historical IS and BS'!E6 -> 0.1917996 | F8: ='Historical IS and BS'!F9/'Historical IS and BS'!F6 -> 0.19235624 | G8: ='Historical IS and BS'!G9/'Historical IS and BS'!G6 -> 0.20127559 | H8: ='Historical IS and BS'!H9/'Historical IS and BS'!H6 -> 0.20962885 | I8: =H8+0.4% -> 0.21362885 | J8: =I8+0.4% -> 0.21762885 | K8: =J8+0.4% -> 0.22162885 | L8: =K8+0.4% -> 0.22562885 | M8: =L8+0.4% -> 0.22962885
B9: Depreciation expenses as % of opening plant & machinery | C9: % | D9: ='Historical IS and BS'!D10/'Historical IS and BS'!C29 -> 0.075478081 | E9: ='Historical IS and BS'!E10/'Historical IS and BS'!D29 -> 0.076019232 | F9: ='Historical IS and BS'!F10/'Historical IS and BS'!E29 -> 0.077798604 | G9: ='Historical IS and BS'!G10/'Historical IS and BS'!F29 -> 0.08104239 | H9: ='Historical IS and BS'!H10/'Historical IS and BS'!G29 -> 0.086511724 | I9: =H9 -> 0.086511724 | J9: =I9 -> 0.086511724 | K9: =J9 -> 0.086511724 | L9: =K9 -> 0.086511724 | M9: =L9 -> 0.086511724
B10: Interest expenses as % of opening total debt | C10: % | D10: ='Historical IS and BS'!D12/('Historical IS and BS'!C35+'Historical IS and BS'!C40) -> 0.038613435 | E10: ='Historical IS and BS'!E12/('Historical IS and BS'!D35+'Historical IS and BS'!D40) -> 0.040933944 | F10: ='Historical IS and BS'!F12/('Historical IS and BS'!E35+'Historical IS and BS'!E40) -> 0.04145407 | G10: ='Historical IS and BS'!G12/('Historical IS and BS'!F35+'Historical IS and BS'!F40) -> 0.049177714 | H10: ='Historical IS and BS'!H12/('Historical IS and BS'!G35+'Historical IS and BS'!G40) -> 0.04530919 | I10: =H10+0.2% -> 0.04730919 | J10: =I10+0.2% -> 0.04930919 | K10: =J10+0.2% -> 0.05130919 | L10: =K10+0.2% -> 0.05330919 | M10: =L10+0.2% -> 0.05530919
B11: Effective tax rate as % of pre-tax profit | C11: % | D11: ='Historical IS and BS'!D14/'Historical IS and BS'!D13 -> 0.31010833 | E11: ='Historical IS and BS'!E14/'Historical IS and BS'!E13 -> 0.32872323 | F11: ='Historical IS and BS'!F14/'Historical IS and BS'!F13 -> 0.32198879 | G11: ='Historical IS and BS'!G14/'Historical IS and BS'!G13 -> 0.30307792 | H11: ='Historical IS and BS'!H14/'Historical IS and BS'!H13 -> 0.30267844 | I11: =H11 -> 0.30267844 | J11: =I11 -> 0.30267844 | K11: =J11 -> 0.30267844 | L11: =K11 -> 0.30267844 | M11: =L11 -> 0.30267844
B12: Minority share of profit as % of total consolidated profit | C12: % | D12: ='Historical IS and BS'!D18/'Historical IS and BS'!D17 -> 0.042633476 | E12: ='Historical IS and BS'!E18/'Historical IS and BS'!E17 -> 0.040311471 | F12: ='Historical IS and BS'!F18/'Historical IS and BS'!F17 -> 0.043043453 | G12: ='Historical IS and BS'!G18/'Historical IS and BS'!G17 -> 0.025596817 | H12: ='Historical IS and BS'!H18/'Historical IS and BS'!H17 -> 0.045476807 | I12: =H12 -> 0.045476807 | J12: =I12 -> 0.045476807 | K12: =J12 -> 0.045476807 | L12: =K12 -> 0.045476807 | M12: =L12 -> 0.045476807
B14: Balance Sheet ratios | C14: Unit | D14: =D5 -> 2013A | E14: =E5 -> 2014A | F14: =F5 -> 2015A | G14: =G5 -> 2016A | H14: =H5 -> 2017A | I14: =I5 -> 2018E | J14: =J5 -> 2019E | K14: =K5 -> 2020E | ... M14: =M5 -> 2022E
B15: Accounts Receivables as % of total revenues | C15: % | D15: ='Historical IS and BS'!D23/'Historical IS and BS'!D6 -> 0.01444145 | E15: ='Historical IS and BS'!E23/'Historical IS and BS'!E6 -> 0.014018652 | F15: ='Historical IS and BS'!F23/'Historical IS and BS'!F6 -> 0.013956524 | G15: ='Historical IS and BS'!G23/'Historical IS and BS'!G6 -> 0.011664904 | H15: ='Historical IS and BS'!H23/'Historical IS and BS'!H6 -> 0.012009311 | I15: =H15 -> 0.012009311 | J15: =I15 -> 0.012009311 | K15: =J15 -> 0.012009311 | L15: =K15 -> 0.012009311 | M15: =L15 -> 0.012009311
B16: Inventory as % of total revenues | C16: % | D16: ='Historical IS and BS'!D24/'Historical IS and BS'!D6 -> 0.09346614 | E16: ='Historical IS and BS'!E24/'Historical IS and BS'!E6 -> 0.094181325 | F16: ='Historical IS and BS'!F24/'Historical IS and BS'!F6 -> 0.092949464 | G16: ='Historical IS and BS'!G24/'Historical IS and BS'!G6 -> 0.09223446 | H16: ='Historical IS and BS'!H24/'Historical IS and BS'!H6 -> 0.088595168 | I16: =H16 -> 0.088595168 | J16: =I16 -> 0.088595168 | K16: =J16 -> 0.088595168 | L16: =K16 -> 0.088595168 | M16: =L16 -> 0.088595168
B17: Plant and machinery as % of total revenues | C17: % | D17: ='Historical IS and BS'!D29/'Historical IS and BS'!D6 -> 0.24897205 | E17: ='Historical IS and BS'!E29/'Historical IS and BS'!E6 -> 0.24755088 | F17: ='Historical IS and BS'!F29/'Historical IS and BS'!F6 -> 0.24020336 | G17: ='Historical IS and BS'!G29/'Historical IS and BS'!G6 -> 0.24166926 | H17: ='Historical IS and BS'!H29/'Historical IS and BS'!H6 -> 0.23499556 | I17: =H17+0.2% -> 0.23699556 | J17: =I17+0.2% -> 0.23899556 | K17: =J17+0.2% -> 0.24099556 | L17: =K17+0.2% -> 0.24299556 | M17: =L17+0.2% -> 0.24499556
B18: Accounts payables as % of total cost of goods sold | C18: % | D18: ='Historical IS and BS'!D36/'Historical IS and BS'!D7 -> 0.11075595 | E18: ='Historical IS and BS'!E36/'Historical IS and BS'!E7 -> 0.10714521 | F18: ='Historical IS and BS'!F36/'Historical IS and BS'!F7 -> 0.10791963 | G18: ='Historical IS and BS'!G36/'Historical IS and BS'!G7 -> 0.10948425 | H18: ='Historical IS and BS'!H36/'Historical IS and BS'!H7 -> 0.11798358 | I18: =H18 -> 0.11798358 | J18: =I18 -> 0.11798358 | K18: =J18 -> 0.11798358 | L18: =K18 -> 0.11798358 | M18: =L18 -> 0.11798358
B20: Key cash flow numbers | C20: Unit | D20: =D14 -> 2013A | E20: =E14 -> 2014A | F20: =F14 -> 2015A | G20: =G14 -> 2016A | H20: =H14 -> 2017A | I20: =I14 -> 2018E | J20: =J14 -> 2019E | K20: =K14 -> 2020E | ... M20: =M14 -> 2022E
B21: Short term borrowings added | C21: USD bn | D21: 2.754 | E21: 0.911 | F21: 0 | G21: 1.235 | H21: 0 | I21: 0 | J21: 0 | K21: 0 | L21: 0 | M21: 0
B22: Short term borrowings repaid | C22: USD bn | D22: 0 | E22: 0 | F22: 6.288 | G22: 0 | H22: 1.673 | I22: =1.099 -> 1.099 | J22: 0 | K22: 0 | L22: 0 | M22: 0
B24: Long term borrowings added | C24: USD bn | D24: 0.211 | E24: 7.072 | F24: 5.174 | G24: 0.039 | H24: 0.137 | I24: 0 | J24: 0 | K24: 0 | L24: 0 | M24: 0
B25: Long term borrowings repaid | C25: USD bn | D25: 1.478 | E25: 4.968 | F25: 3.904 | G25: 4.432 | H25: 2.055 | I25: =2.256+0.894 -> 3.15 | J25: =(4.039+1.624)/2 -> 2.8315 | K25: =(4.039+1.624)/2 -> 2.8315 | L25: =(4.394+1.395)/2 -> 2.8945 | M25: =(4.394+1.395)/2 -> 2.8945
B27: Dividends paid to common shareholders (USD bn) | C27: USD bn | D27: 5.361 | E27: 6.139 | F27: 6.185 | G27: 6.294 | H27: 6.216 | I27: =AVERAGE(D27:H27) -> 6.039 | J27: =I27 -> 6.039 | K27: =J27 -> 6.039 | L27: =K27 -> 6.039 | M27: =L27 -> 6.039
B28: Common equity sharebuy back (USD bn) | C28: USD bn | D28: 7.6 | E28: 6.683 | F28: 1.015 | G28: 4.112 | H28: 8.298 | I28: =9.2/5 -> 1.84 | J28: =9.2/5 -> 1.84 | K28: =9.2/5 -> 1.84 | L28: =9.2/5 -> 1.84 | M28: =9.2/5 -> 1.84
B29: Dividend payout ratio as % of total profit | C29: % | D29: =D27/'Historical IS and BS'!D19 -> 0.31537149 | E29: =E27/'Historical IS and BS'!E19 -> 0.38316065 | F29: =F27/'Historical IS and BS'!F19 -> 0.37798692 | G29: =G27/'Historical IS and BS'!G19 -> 0.4283381 | H29: =H27/'Historical IS and BS'!H19 -> 0.45561827

Sheet Forecasted IS and BS
A1: WAL-MART STORES, INC.
A2: Forecasted standardized financial statements - Income statement and Balance sheet
A3: U$ bn
C4: HISTORICAL | I4: FORECASTED
B5: Income Statement | C5: 2012A | D5: 2013A | E5: 2014A | F5: 2015A | G5: 2016A | H5: 2017A | I5: 2018E | J5: 2019E | K5: 2020E | L5: 2021E | M5: 2022E
B6: Revenues | C6: =446.509 -> 446.509 | D6: =468.651 -> 468.651 | E6: 476.294 | F6: 485.651 | G6: 482.13 | H6: 485.873 | I6: =H6*(1+'Key ratios'!I6) -> 490.6168 | J6: =I6*(1+'Key ratios'!J6) -> 496.38816 | K6: =J6*(1+'Key ratios'!K6) -> 503.22018 | L6: =K6*(1+'Key ratios'!L6) -> 511.15267 | M6: =L6*(1+'Key ratios'!M6) -> 520.23252
B7: Cost of goods sold (excluding depreciation and amortization cost) | C7: =334.993-8.106 -> 326.887 | D7: =352.297-8.478 -> 343.819 | E7: =358.069-8.87 -> 349.199 | F7: =365.086-9.173 -> 355.913 | G7: =360.984-9.454 -> 351.53 | H7: =361.256-H10 -> 351.802 | I7: ='Key ratios'!I7*'Forecasted IS and BS'!I6 -> 353.62346 | J7: ='Key ratios'!J7*'Forecasted IS and BS'!J6 -> 356.79052 | K7: ='Key ratios'!K7*'Forecasted IS and BS'!K6 -> 360.69476 | L7: ='Key ratios'!L7*'Forecasted IS and BS'!L6 -> 365.35825 | M7: ='Key ratios'!M7*'Forecasted IS and BS'!M6 -> 370.80781
B8: Gross profit | C8: =C6-C7 -> 119.622 | D8: =D6-D7 -> 124.832 | E8: =E6-E7 -> 127.095 | F8: =F6-F7 -> 129.738 | G8: =G6-G7 -> 130.6 | H8: =H6-H7 -> 134.071 | I8: =I6-I7 -> 136.99334 | J8: =J6-J7 -> 139.59764 | ... M8: =M6-M7 -> 149.4247 | P8: s
B9: SG&A expenses | C9: =85.025 -> 85.025 | D9: =88.629 -> 88.629 | E9: 91.353 | F9: 93.418 | G9: =97.041 -> 97.041 | H9: =101.853 -> 101.853 | I9: ='Key ratios'!I8*'Forecasted IS and BS'!I6 -> 104.80991 | J9: ='Key ratios'!J8*'Forecasted IS and BS'!J6 -> 108.02839 | K9: ='Key ratios'!K8*'Forecasted IS and BS'!K6 -> 111.52811 | L9: ='Key ratios'!L8*'Forecasted IS and BS'!L6 -> 115.33079 | M9: ='Key ratios'!M8*'Forecasted IS and BS'!M6 -> 119.4604
B10: Depreciation and Amortization cost | C10: =8.106 -> 8.106 | D10: =8.478 -> 8.478 | E10: 8.87 | F10: 9.173 | G10: 9.454 | H10: 9.454 | I10: ='Key ratios'!I9*'Forecasted IS and BS'!H29 -> 9.8777356 | J10: ='Key ratios'!J9*'Forecasted IS and BS'!I29 -> 10.059065 | K10: ='Key ratios'!K9*'Forecasted IS and BS'!J29 -> 10.263281 | L10: ='Key ratios'!L9*'Forecasted IS and BS'!K29 -> 10.491608 | M10: ='Key ratios'!M9*'Forecasted IS and BS'!L29 -> 10.745434
B11: EBIT | C11: =C8-C9-C10 -> 26.491 | D11: =D8-D9-D10 -> 27.725 | E11: =E8-E9-E10 -> 26.872 | F11: =F8-F9-F10 -> 27.147 | G11: =G8-G9-G10 -> 24.105 | H11: =H8-H9-H10 -> 22.764 | I11: =I8-I9-I10 -> 22.305702 | J11: =J8-J9-J10 -> 21.510185 | ... M11: =M8-M9-M10 -> 19.218873
B12: Interest expense (net of interest income) | C12: =2.159 -> 2.159 | D12: =2.063 -> 2.063 | E12: 2.216 | F12: 2.348 | G12: =2.467 -> 2.467 | H12: =2.267 -> 2.267 | I12: ='Key ratios'!I10*('Forecasted IS and BS'!H35+'Forecasted IS and BS'!H40) -> 2.1732896 | J12: ='Key ratios'!J10*('Forecasted IS and BS'!I35+'Forecasted IS and BS'!I40) -> 2.0556508 | K12: ='Key ratios'!K10*('Forecasted IS and BS'!J35+'Forecasted IS and BS'!J40) -> 1.9937468 | L12: ='Key ratios'!L10*('Forecasted IS and BS'!K35+'Forecasted IS and BS'!K40) -> 1.9205169 | M12: ='Key ratios'!M10*('Forecasted IS and BS'!L35+'Forecasted IS and BS'!L40) -> 1.8324764
B13: EBT | C13: =C11-C12 -> 24.332 | D13: =D11-D12 -> 25.662 | E13: =E11-E12 -> 24.656 | F13: =F11-F12 -> 24.799 | G13: =G11-G12 -> 21.638 | H13: =H11-H12 -> 20.497 | I13: =I11-I12 -> 20.132413 | J13: =J11-J12 -> 19.454535 | ... M13: =M11-M12 -> 17.386396
B14: Provisions for taxes | C14: =7.924 -> 7.924 | D14: =7.958 -> 7.958 | E14: 8.105 | F14: 7.985 | G14: =6.558 -> 6.558 | H14: 6.204 | I14: ='Key ratios'!I11*'Forecasted IS and BS'!I13 -> 6.0936472 | J14: ='Key ratios'!J11*'Forecasted IS and BS'!J13 -> 5.8884682 | K14: ='Key ratios'!K11*'Forecasted IS and BS'!K13 -> 5.67228 | L14: ='Key ratios'!L11*'Forecasted IS and BS'!L13 -> 5.4638019 | M14: ='Key ratios'!M11*'Forecasted IS and BS'!M13 -> 5.2624873
B15: Profits after tax (continuing operations) | C15: =C13-C14 -> 16.408 | D15: =D13-D14 -> 17.704 | E15: =E13-E14 -> 16.551 | F15: =F13-F14 -> 16.814 | G15: =G13-G14 -> 15.08 | H15: =H13-H14 -> 14.293 | I15: =I13-I14 -> 14.038765 | J15: =J13-J14 -> 13.566066 | ... M15: =M13-M14 -> 12.123909
B16: Income from discontinued operations (net of taxes) | C16: -0.021 | D16: 0.052 | E16: 0.144 | F16: 0.285 | G16: 0 | H16: 0 | I16: 0 | J16: 0 | K16: 0 | L16: 0 | M16: 0
B17: Consolidated net income | C17: =C15+C16 -> 16.387 | D17: =D15+D16 -> 17.756 | E17: =E15+E16 -> 16.695 | F17: =F15+F16 -> 17.099 | G17: =G15+G16 -> 15.08 | H17: =H15+H16 -> 14.293 | I17: =I15+I16 -> 14.038765 | J17: =J15+J16 -> 13.566066 | ... M17: =M15+M16 -> 12.123909
B18: Minority interest share of profits | C18: 0.688 | D18: 0.757 | E18: 0.673 | F18: 0.736 | G18: 0.386 | H18: 0.65 | I18: ='Key ratios'!I12*'Forecasted IS and BS'!I17 -> 0.63843822 | J18: ='Key ratios'!J12*'Forecasted IS and BS'!J17 -> 0.61694138 | K18: ='Key ratios'!K12*'Forecasted IS and BS'!K17 -> 0.5942911 | L18: ='Key ratios'!L12*'Forecasted IS and BS'!L17 -> 0.57244862 | M18: ='Key ratios'!M12*'Forecasted IS and BS'!M17 -> 0.55135667
B19: Consolidated net income attributable to Walmart | C19: =C17-C18 -> 15.699 | D19: =D17-D18 -> 16.999 | E19: =E17-E18 -> 16.022 | F19: =F17-F18 -> 16.363 | G19: =G17-G18 -> 14.694 | H19: =H17-H18 -> 13.643 | I19: =I17-I18 -> 13.400327 | J19: =J17-J18 -> 12.949125 | ... M19: =M17-M18 -> 11.572552
B21: Balance Sheet - Assets | C21: =C5 -> 2012A | D21: =D5 -> 2013A | E21: =E5 -> 2014A | F21: =F5 -> 2015A | G21: =G5 -> 2016A | H21: =H5 -> 2017A | I21: =I5 -> 2018E | J21: =J5 -> 2019E | ... M21: =M5 -> 2022E
B22: Cash | C22: =6.55 -> 6.55 | D22: =7.781 -> 7.781 | E22: =7.281 -> 7.281 | F22: 9.135 | G22: 8.705 | H22: 6.867 | I22: ='Forecasted CF statement'!I31 -> 6.4932709 | J22: ='Forecasted CF statement'!J31 -> 6.7813127 | K22: ='Forecasted CF statement'!K31 -> 6.2728572 | L22: ='Forecasted CF statement'!L31 -> 4.905232 | M22: ='Forecasted CF statement'!M31 -> 2.7383005
B23: Accounts Receivables | C23: =5.937 -> 5.937 | D23: =6.768 -> 6.768 | E23: =6.677 -> 6.677 | F23: =6.778 -> 6.778 | G23: 5.624 | H23: 5.835 | I23: ='Key ratios'!I15*'Forecasted IS and BS'!I6 -> 5.8919698 | J23: ='Key ratios'!J15*'Forecasted IS and BS'!J6 -> 5.9612798 | K23: ='Key ratios'!K15*'Forecasted IS and BS'!K6 -> 6.0433277 | L23: ='Key ratios'!L15*'Forecasted IS and BS'!L6 -> 6.1385915 | M23: ='Key ratios'!M15*'Forecasted IS and BS'!M6 -> 6.2476341
B24: Inventory | C24: =40.714 -> 40.714 | D24: =43.803 -> 43.803 | E24: =44.858 -> 44.858 | F24: 45.141 | G24: 44.469 | H24: 43.046 | I24: ='Key ratios'!I16*'Forecasted IS and BS'!I6 -> 43.466278 | J24: ='Key ratios'!J16*'Forecasted IS and BS'!J6 -> 43.977592 | K24: ='Key ratios'!K16*'Forecasted IS and BS'!K6 -> 44.582876 | L24: ='Key ratios'!L16*'Forecasted IS and BS'!L6 -> 45.285657 | M24: ='Key ratios'!M16*'Forecasted IS and BS'!M6 -> 46.090087
B25: Other current assets | C25: 1.685 | D25: 1.551 | E25: 1.909 | F25: 2.224 | G25: 1.441 | H25: 1.941 | I25: =H25 -> 1.941 | J25: =I25 -> 1.941 | K25: =J25 -> 1.941 | L25: =K25 -> 1.941 | M25: =L25 -> 1.941
B26: Current assets of discontinued operations | C26: 0.089 | D26: 0.037 | E26: 0.46 | F26: 0 | G26: 0 | H26: 0 | I26: 0 | J26: 0 | K26: 0 | L26: 0 | M26: 0
B27: Total current assets | C27: =SUM(C22:C26) -> 54.975 | D27: =SUM(D22:D26) -> 59.94 | E27: =SUM(E22:E26) -> 61.185 | F27: =SUM(F22:F26) -> 63.278 | G27: =SUM(G22:G26) -> 60.239 | H27: =SUM(H22:H26) -> 57.689 | I27: =SUM(I22:I26) -> 57.792519 | J27: =SUM(J22:J26) -> 58.661185 | ... M27: =SUM(M22:M26) -> 57.017022
B29: Plant and Machinery | C29: =109.603+2.721 -> 112.324 | D29: =113.929+2.752 -> 116.681 | E29: =115.364+2.543 -> 117.907 | F29: =114.28+2.375 -> 116.655 | G29: =110.171+6.345 -> 116.516 | H29: =107.71+6.468 -> 114.178 | I29: ='Key ratios'!I17*'Forecasted IS and BS'!I6 -> 116.27401 | J29: ='Key ratios'!J17*'Forecasted IS and BS'!J6 -> 118.63457 | K29: ='Key ratios'!K17*'Forecasted IS and BS'!K6 -> 121.27383 | L29: ='Key ratios'!L17*'Forecasted IS and BS'!L6 -> 124.20783 | M29: ='Key ratios'!M17*'Forecasted IS and BS'!M6 -> 127.45466
B30: Goodwill | C30: =20.651 -> 20.651 | D30: =20.497 -> 20.497 | E30: =19.51 -> 19.51 | F30: =18.102 -> 18.102 | G30: =16.695 -> 16.695 | H30: 17.037 | I30: =H30 -> 17.037 | J30: =I30 -> 17.037 | K30: =J30 -> 17.037 | L30: =K30 -> 17.037 | M30: =L30 -> 17.037
B31: Other long term assets | C31: =5.456 -> 5.456 | D31: =5.987 -> 5.987 | E31: =6.149 -> 6.149 | F31: =5.455 -> 5.455 | G31: =6.131 -> 6.131 | H31: 9.921 | I31: =H31 -> 9.921 | J31: =I31 -> 9.921 | K31: =J31 -> 9.921 | L31: =K31 -> 9.921 | M31: =L31 -> 9.921
B32: Total assets | C32: =C27+C29+C31+C30 -> 193.406 | D32: =D27+D29+D31+D30 -> 203.105 | E32: =E27+E29+E31+E30 -> 204.751 | F32: =F27+F29+F31+F30 -> 203.49 | G32: =G27+G29+G31+G30 -> 199.581 | H32: =H27+H29+H31+H30 -> 198.825 | I32: =SUM(I27:I31) -> 201.02453 | J32: =SUM(J27:J31) -> 204.25375 | K32: =SUM(K27:K31) -> 207.07189 | L32: =SUM(L27:L31) -> 209.43631 | M32: =SUM(M27:M31) -> 211.42968
B34: Balance Sheet - Liabilities and equity | C34: =C21 -> 2012A | D34: =D21 -> 2013A | E34: =E21 -> 2014A | F34: =F21 -> 2015A | G34: =G21 -> 2016A | H34: =H21 -> 2017A | I34: =I21 -> 2018E | J34: =J21 -> 2019E | ... M34: =M21 -> 2022E
B35: Short term debt | C35: =4.047+1.975+0.326 -> 6.348 | D35: =6.805+5.587+0.327 -> 12.719 | E35: =7.67+4.103+0.309 -> 12.082 | F35: =1.592+4.791+0.287 -> 6.67 | G35: =2.708+2.745+0.551 -> 6.004 | H35: =1.099+2.256+0.565 -> 3.92 | I35: =H35+'Key ratios'!I21-'Key ratios'!I22 -> 2.821 | J35: =I35+'Key ratios'!J21-'Key ratios'!J22 -> 2.821 | K35: =J35+'Key ratios'!K21-'Key ratios'!K22 -> 2.821 | L35: =K35+'Key ratios'!L21-'Key ratios'!L22 -> 2.821 | M35: =L35+'Key ratios'!M21-'Key ratios'!M22 -> 2.821
B36: Accounts payable | C36: =36.608 -> 36.608 | D36: =38.08 -> 38.08 | E36: =37.415 -> 37.415 | F36: 38.41 | G36: 38.487 | H36: 41.433 | I36: ='Key ratios'!I18*'Forecasted IS and BS'!I7 -> 41.72176 | J36: ='Key ratios'!J18*'Forecasted IS and BS'!J7 -> 42.095421 | K36: ='Key ratios'!K18*'Forecasted IS and BS'!K7 -> 42.556057 | L36: ='Key ratios'!L18*'Forecasted IS and BS'!L7 -> 43.106273 | M36: ='Key ratios'!M18*'Forecasted IS and BS'!M7 -> 43.749232
B37: Other short term liabilities | C37: =18.154+1.164+0.026 -> 19.344 | D37: =18.808+2.211 -> 21.019 | E37: =18.793+0.966+0.089 -> 19.848 | F37: =19.152+1.021 -> 20.173 | G37: =19.607+0.521 -> 20.128 | H37: =20.654+0.921 -> 21.575 | I37: =H37 -> 21.575 | J37: =I37 -> 21.575 | K37: =J37 -> 21.575 | L37: =K37 -> 21.575 | M37: =L37 -> 21.575
B38: Total current liabilities | C38: =SUM(C35:C37) -> 62.3 | D38: =SUM(D35:D37) -> 71.818 | E38: =SUM(E35:E37) -> 69.345 | F38: =SUM(F35:F37) -> 65.253 | G38: =SUM(G35:G37) -> 64.619 | H38: =SUM(H35:H37) -> 66.928 | I38: =SUM(I35:I37) -> 66.11776 | J38: =SUM(J35:J37) -> 66.491421 | ... M38: =SUM(M35:M37) -> 68.145232
B40: Long term debt | C40: =44.07+3.009 -> 47.079 | D40: =38.394+3.023 -> 41.417 | E40: =41.771+2.788 -> 44.559 | F40: =40.889+2.606 -> 43.495 | G40: =38.214+5.816 -> 44.03 | H40: =36.015+6.003 -> 42.018 | I40: =H40+'Key ratios'!I24-'Key ratios'!I25 -> 38.868 | J40: =I40+'Key ratios'!J24-'Key ratios'!J25 -> 36.0365 | K40: =J40+'Key ratios'!K24-'Key ratios'!K25 -> 33.205 | L40: =K40+'Key ratios'!L24-'Key ratios'!L25 -> 30.3105 | M40: =L40+'Key ratios'!M24-'Key ratios'!M25 -> 27.416
B41: Other long term liabilities | C41: =7.862+0.404 -> 8.266 | D41: =7.613+0.519 -> 8.132 | E41: =8.017+1.491 -> 9.508 | F41: =8.805 -> 8.805 | G41: =7.321 -> 7.321 | H41: 9.344 | I41: =H41 -> 9.344 | J41: =I41 -> 9.344 | K41: =J41 -> 9.344 | L41: =K41 -> 9.344 | M41: =L41 -> 9.344
B43: Minority interest | C43: 4.446 | D43: 5.395 | E43: 5.084 | F43: 4.543 | G43: 3.065 | H43: 2.737 | I43: =H43+I18 -> 3.3754382 | J43: =I43+J18 -> 3.9923796 | K43: =J43+K18 -> 4.5866707 | L43: =K43+L18 -> 5.1591193 | M43: =L43+M18 -> 5.710476
B44: Common equity | C44: 71.315 | D44: =76.343 -> 76.343 | E44: 76.255 | F44: 81.394 | G44: 80.546 | H44: 77.798 | I44: =H44+I19-'Key ratios'!I27-'Key ratios'!I28 -> 83.319327 | J44: =I44+J19-'Key ratios'!J27-'Key ratios'!J28 -> 88.389452 | K44: =J44+K19-'Key ratios'!K27-'Key ratios'!K28 -> 92.984165 | L44: =K44+L19-'Key ratios'!L27-'Key ratios'!L28 -> 97.120421 | M44: =L44+M19-'Key ratios'!M27-'Key ratios'!M28 -> 100.81397
B45: Total liabilities and equity | C45: =C44+C40+C41+C38+C43 -> 193.406 | D45: =D44+D40+D41+D38+D43 -> 203.105 | E45: =E44+E40+E41+E38+E43 -> 204.751 | F45: =F44+F40+F41+F38+F43 -> 203.49 | G45: =G44+G40+G41+G38+G43 -> 199.581 | H45: =H44+H40+H41+H38+H43 -> 198.825 | I45: =SUM(I38,I40:I41,I43:I44) -> 201.02453 | J45: =SUM(J38,J40:J41,J43:J44) -> 204.25375 | K45: =SUM(K38,K40:K41,K43:K44) -> 207.07189 | L45: =SUM(L38,L40:L41,L43:L44) -> 209.43631 | M45: =SUM(M38,M40:M41,M43:M44) -> 211.42968
...

Sheet Forecasted CF statement
A1: WAL-MART STORES, INC.
A2: Forecasted Cash flow statement
A3: USD bn
B5: Cash flow statement | I5: ='Forecasted IS and BS'!I5 -> 2018E | J5: ='Forecasted IS and BS'!J5 -> 2019E | K5: ='Forecasted IS and BS'!K5 -> 2020E | L5: ='Forecasted IS and BS'!L5 -> 2021E | M5: ='Forecasted IS and BS'!M5 -> 2022E
B6: Cash flow from operations | I6: =SUM(I7:I11)-SUM(I12:I14) -> 25.901303 | J6: =SUM(J7:J11)-SUM(J12:J14) -> 25.473819 | K6: =SUM(K7:K11)-SUM(K12:K14) -> 25.098336 | L6: =SUM(L7:L11)-SUM(L12:L14) -> 24.752001 | M6: =SUM(M7:M11)-SUM(M12:M14) -> 24.431305
B7: Consolidated net income from continuing operations | I7: ='Forecasted IS and BS'!I15 -> 14.038765 | J7: ='Forecasted IS and BS'!J15 -> 13.566066 | K7: ='Forecasted IS and BS'!K15 -> 13.068004 | L7: ='Forecasted IS and BS'!L15 -> 12.587705 | M7: ='Forecasted IS and BS'!M15 -> 12.123909
B8: Add: Depreciation and amortization | I8: ='Forecasted IS and BS'!I10 -> 9.8777356 | J8: ='Forecasted IS and BS'!J10 -> 10.059065 | K8: ='Forecasted IS and BS'!K10 -> 10.263281 | L8: ='Forecasted IS and BS'!L10 -> 10.491608 | M8: ='Forecasted IS and BS'!M10 -> 10.745434
B9: Add: Interest expense | I9: ='Forecasted IS and BS'!I12 -> 2.1732896 | J9: ='Forecasted IS and BS'!J12 -> 2.0556508 | K9: ='Forecasted IS and BS'!K12 -> 1.9937468 | L9: ='Forecasted IS and BS'!L12 -> 1.9205169 | M9: ='Forecasted IS and BS'!M12 -> 1.8324764
B10: Add: Increase in accounts payable | I10: ='Forecasted IS and BS'!I36-'Forecasted IS and BS'!H36 -> 0.28876025 | J10: ='Forecasted IS and BS'!J36-'Forecasted IS and BS'!I36 -> 0.37366122 | K10: ='Forecasted IS and BS'!K36-'Forecasted IS and BS'!J36 -> 0.46063548 | L10: ='Forecasted IS and BS'!L36-'Forecasted IS and BS'!K36 -> 0.55021573 | M10: ='Forecasted IS and BS'!M36-'Forecasted IS and BS'!L36 -> 0.64295904
B11: Add: Increase in other short term liabilities | I11: ='Forecasted IS and BS'!I37-'Forecasted IS and BS'!H37 -> 0 | J11: ='Forecasted IS and BS'!J37-'Forecasted IS and BS'!I37 -> 0 | K11: ='Forecasted IS and BS'!K37-'Forecasted IS and BS'!J37 -> 0 | L11: ='Forecasted IS and BS'!L37-'Forecasted IS and BS'!K37 -> 0 | M11: ='Forecasted IS and BS'!M37-'Forecasted IS and BS'!L37 -> 0
B12: Less: Increase in inventory | I12: ='Forecasted IS and BS'!I24-'Forecasted IS and BS'!H24 -> 0.42027817 | J12: ='Forecasted IS and BS'!J24-'Forecasted IS and BS'!I24 -> 0.5113141 | K12: ='Forecasted IS and BS'!K24-'Forecasted IS and BS'!J24 -> 0.60528411 | L12: ='Forecasted IS and BS'!L24-'Forecasted IS and BS'!K24 -> 0.70278067 | M12: ='Forecasted IS and BS'!M24-'Forecasted IS and BS'!L24 -> 0.80443024
B13: Less: Increase in accounts receivables | I13: ='Forecasted IS and BS'!I23-'Forecasted IS and BS'!H23 -> 0.056969826 | J13: ='Forecasted IS and BS'!J23-'Forecasted IS and BS'!I23 -> 0.069309988 | K13: ='Forecasted IS and BS'!K23-'Forecasted IS and BS'!J23 -> 0.082047874 | L13: ='Forecasted IS and BS'!L23-'Forecasted IS and BS'!K23 -> 0.095263792 | M13: ='Forecasted IS and BS'!M23-'Forecasted IS and BS'!L23 -> 0.10904266
B14: Less: Increase in other short term assets | I14: ='Forecasted IS and BS'!I25-'Forecasted IS and BS'!H25 -> 0 | J14: ='Forecasted IS and BS'!J25-'Forecasted IS and BS'!I25 -> 0 | K14: ='Forecasted IS and BS'!K25-'Forecasted IS and BS'!J25 -> 0 | L14: ='Forecasted IS and BS'!L25-'Forecasted IS and BS'!K25 -> 0 | M14: ='Forecasted IS and BS'!M25-'Forecasted IS and BS'!L25 -> 0
B16: Cash flow from investment | I16: =-(I17+I18) -> -11.973742 | J16: =-(J17+J18) -> -12.419626 | K16: =-(K17+K18) -> -12.902544 | L16: =-(L17+L18) -> -13.42561 | M16: =-(M17+M18) -> -13.99226
B17: Less: Capex in plant and machinery | I17: ='Forecasted IS and BS'!I29-'Forecasted IS and BS'!H29+'Forecasted IS and BS'!I10 -> 11.973742 | J17: ='Forecasted IS and BS'!J29-'Forecasted IS and BS'!I29+'Forecasted IS and BS'!J10 -> 12.419626 | K17: ='Forecasted IS and BS'!K29-'Forecasted IS and BS'!J29+'Forecasted IS and BS'!K10 -> 12.902544 | L17: ='Forecasted IS and BS'!L29-'Forecasted IS and BS'!K29+'Forecasted IS and BS'!L10 -> 13.42561 | M17: ='Forecasted IS and BS'!M29-'Forecasted IS and BS'!L29+'Forecasted IS and BS'!M10 -> 13.99226
B18: Less: Increase in goodwill | I18: ='Forecasted IS and BS'!I30-'Forecasted IS and BS'!H30 -> 0 | J18: ='Forecasted IS and BS'!J30-'Forecasted IS and BS'!I30 -> 0 | K18: ='Forecasted IS and BS'!K30-'Forecasted IS and BS'!J30 -> 0 | L18: ='Forecasted IS and BS'!L30-'Forecasted IS and BS'!K30 -> 0 | M18: ='Forecasted IS and BS'!M30-'Forecasted IS and BS'!L30 -> 0
B20: Cash flow from financing | I20: =SUM(I21:I22)-SUM(I23:I27) -> -14.30129 | J20: =SUM(J21:J22)-SUM(J23:J27) -> -12.766151 | K20: =SUM(K21:K22)-SUM(K23:K27) -> -12.704247 | L20: =SUM(L21:L22)-SUM(L23:L27) -> -12.694017 | M20: =SUM(M21:M22)-SUM(M23:M27) -> -12.605976
B21: Add: New short term debt to be raised | I21: ='Key ratios'!I21 -> 0 | J21: ='Key ratios'!J21 -> 0 | K21: ='Key ratios'!K21 -> 0 | L21: ='Key ratios'!L21 -> 0 | M21: ='Key ratios'!M21 -> 0
B22: Add: New long term debt to be raised | I22: ='Key ratios'!I24 -> 0 | J22: ='Key ratios'!J24 -> 0 | K22: ='Key ratios'!K24 -> 0 | L22: ='Key ratios'!L24 -> 0 | M22: ='Key ratios'!M24 -> 0
B23: Less: Interest expense | I23: ='Forecasted IS and BS'!I12 -> 2.1732896 | J23: ='Forecasted IS and BS'!J12 -> 2.0556508 | K23: ='Forecasted IS and BS'!K12 -> 1.9937468 | L23: ='Forecasted IS and BS'!L12 -> 1.9205169 | M23: ='Forecasted IS and BS'!M12 -> 1.8324764
B24: Less: Short term debt to be repaid | I24: ='Key ratios'!I22 -> 1.099 | J24: ='Key ratios'!J22 -> 0 | K24: ='Key ratios'!K22 -> 0 | L24: ='Key ratios'!L22 -> 0 | M24: ='Key ratios'!M22 -> 0
B25: Less: Long term debt to be repaid | I25: ='Key ratios'!I25 -> 3.15 | J25: ='Key ratios'!J25 -> 2.8315 | K25: ='Key ratios'!K25 -> 2.8315 | L25: ='Key ratios'!L25 -> 2.8945 | M25: ='Key ratios'!M25 -> 2.8945
B26: Less: Dividends to be paid to common shareholders | I26: ='Key ratios'!I27 -> 6.039 | J26: ='Key ratios'!J27 -> 6.039 | K26: ='Key ratios'!K27 -> 6.039 | L26: ='Key ratios'!L27 -> 6.039 | M26: ='Key ratios'!M27 -> 6.039
B27: Less: Share buyback from common shareholders | I27: ='Key ratios'!I28 -> 1.84 | J27: ='Key ratios'!J28 -> 1.84 | K27: ='Key ratios'!K28 -> 1.84 | L27: ='Key ratios'!L28 -> 1.84 | M27: ='Key ratios'!M28 -> 1.84
B29: Net cash flows | I29: =I6+I16+I20 -> -0.37372911 | J29: =J6+J16+J20 -> 0.28804186 | K29: =K6+K16+K20 -> -0.50845551 | L29: =L6+L16+L20 -> -1.3676252 | M29: =M6+M16+M20 -> -2.1669315
B30: Opening cash balance | I30: ='Forecasted IS and BS'!H22 -> 6.867 | J30: =I31 -> 6.4932709 | K30: =J31 -> 6.7813127 | L30: =K31 -> 6.2728572 | M30: =L31 -> 4.905232
B31: Closing cash balance | G31: 8.705 | I31: =I29+I30 -> 6.4932709 | J31: =J29+J30 -> 6.7813127 | K31: =K29+K30 -> 6.2728572 | L31: =L29+L30 -> 4.905232 | M31: =M29+M30 -> 2.7383005

Sheet Valuation
A1: WAL-MART STORES, INC.
A2: DISCOUNTED CASH FLOW TECHNIQUE OF VALUATION
A3: USD bn
B5: Free cash flow to firm calculation (FCFF)
B6: Operating cash profit calculation | H6: FY 2017A | I6: FY2018E | J6: FY2019E | K6: FY2020E | L6: FY2021E | M6: FY2022E
B7: Revenues | I7: ='Forecasted IS and BS'!I6 -> 490.6168 | J7: ='Forecasted IS and BS'!J6 -> 496.38816 | K7: ='Forecasted IS and BS'!K6 -> 503.22018 | L7: ='Forecasted IS and BS'!L6 -> 511.15267 | M7: ='Forecasted IS and BS'!M6 -> 520.23252
B8: Less: Operating expenses (COGS + SGA) | I8: ='Forecasted IS and BS'!I7+'Forecasted IS and BS'!I9 -> 458.43337 | J8: ='Forecasted IS and BS'!J7+'Forecasted IS and BS'!J9 -> 464.81891 | K8: ='Forecasted IS and BS'!K7+'Forecasted IS and BS'!K9 -> 472.22287 | L8: ='Forecasted IS and BS'!L7+'Forecasted IS and BS'!L9 -> 480.68904 | M8: ='Forecasted IS and BS'!M7+'Forecasted IS and BS'!M9 -> 490.26821
B9: Less: Depreciation | I9: ='Forecasted IS and BS'!I10 -> 9.8777356 | J9: ='Forecasted IS and BS'!J10 -> 10.059065 | K9: ='Forecasted IS and BS'!K10 -> 10.263281 | L9: ='Forecasted IS and BS'!L10 -> 10.491608 | M9: ='Forecasted IS and BS'!M10 -> 10.745434
B10: Earnings before interest and tax (EBIT) | I10: =I7-I8-I9 -> 22.305702 | J10: =J7-J8-J9 -> 21.510185 | K10: =K7-K8-K9 -> 20.734031 | L10: =L7-L8-L9 -> 19.972024 | M10: =M7-M8-M9 -> 19.218873
B11: Less: Operating taxes | I11: ='Key ratios'!I11*Valuation!I10 -> 6.7514551 | J11: ='Key ratios'!J11*Valuation!J10 -> 6.5106694 | K11: ='Key ratios'!K11*Valuation!K10 -> 6.2757442 | L11: ='Key ratios'!L11*Valuation!L10 -> 6.045101 | M11: ='Key ratios'!M11*Valuation!M10 -> 5.8171384
B12: Post tax operating profit (NOPLAT) | I12: =I10-I11 -> 15.554247 | J12: =J10-J11 -> 14.999516 | K12: =K10-K11 -> 14.458287 | L12: =L10-L11 -> 13.926923 | M12: =M10-M11 -> 13.401734
B13: Add: Depreciation | I13: =I9 -> 9.8777356 | J13: =J9 -> 10.059065 | K13: =K9 -> 10.263281 | L13: =L9 -> 10.491608 | M13: =M9 -> 10.745434
B14: Post tax operating cash profit | I14: =I12+I13 -> 25.431983 | J14: =J12+J13 -> 25.058581 | K14: =K12+K13 -> 24.721568 | L14: =L12+L13 -> 24.418531 | M14: =M12+M13 -> 24.147168
B16: Operating cash investments | H16: =H6 -> FY 2017A | I16: =I6 -> FY2018E | J16: =J6 -> FY2019E | K16: =K6 -> FY2020E | L16: =L6 -> FY2021E | M16: =M6 -> FY2022E
B17: Capital expenditures investments | I17: 11.360304 | J17: 11.794927 | K17: 12.265162 | L17: 12.774047 | M17: 13.324935
B19: Working Capital | H19: -12.186 | I19: -11.997718 | J19: -11.790966 | K19: -11.564487 | L19: -11.316883 | M19: -11.046602
B20: Increase in working capital | I20: =I19-H19 -> 0.18828174 | J20: =J19-I19 -> 0.20675202 | K20: =K19-J19 -> 0.22647947 | L20: =L19-K19 -> 0.24760412 | M20: =M19-L19 -> 0.27028018
B21: Operating cash investments | I21: =I17+I20 -> 11.548585 | J21: =J17+J20 -> 12.001679 | K21: =K17+K20 -> 12.491641 | L21: =L17+L20 -> 13.021651 | M21: =M17+M20 -> 13.595215
B23: Free cash flow to firm | H23: =H16 -> FY 2017A | I23: =I16 -> FY2018E | J23: =J16 -> FY2019E | K23: =K16 -> FY2020E | L23: =L16 -> FY2021E | M23: =M16 -> FY2022E
B24: FCFF | I24: =I14-I21 -> 13.883397 | J24: =J14-J21 -> 13.056902 | K24: =K14-K21 -> 12.229927 | L24: =L14-L21 -> 11.396879 | M24: =M14-M21 -> 10.551953
B26: Cost of Capital calculation | H26: Percent
B27: Tax rate | H27: 0.31 | I27: 2017 tax rate
B28: Cost of debt | H28: 0.02 | I28: Bloomberg
B29: Cost of equity | H29: 0.063 | I29: Bloomberg
B30: Target capital structure (debt to capital) | H30: 0.15 | I30: Bloomberg
B31: WACC (Weighted average cost of capital) | H31: =H28*(1-H27)*H30+H29*(1-H30) -> 0.05562 | I31: WACC=% of debt in total capital*post tax cost of debt+% of equity*cost of equity
B33: Present value of future cash flows | H33: =H23 -> FY 2017A | I33: =I23 -> FY2018E | J33: =J23 -> FY2019E | K33: =K23 -> FY2020E | L33: =L23 -> FY2021E | M33: =M23 -> FY2022E
B34: Years from current | I34: 1 | J34: 2 | K34: 3 | L34: 4 | M34: 5
B35: Discount factor | I35: =1/(1+$H$31)^I34 -> 0.94731059 | J35: =1/(1+$H$31)^J34 -> 0.89739734 | K35: =1/(1+$H$31)^K34 -> 0.850114 | L35: =1/(1+$H$31)^L34 -> 0.80532199 | M35: =1/(1+$H$31)^M34 -> 0.76289005
B36: Present value of FCFF | I36: =I24*I35 -> 13.151889 | J36: =J24*J35 -> 11.717229 | K36: =K24*K35 -> 10.396832 | L36: =L24*L35 -> 9.1781577 | M36: =M24*M35 -> 8.04998
B38: Terminal value calculation | H38: =H33 -> FY 2017A | I38: =I33 -> FY2018E | J38: =J33 -> FY2019E | K38: =K33 -> FY2020E | L38: =L33 -> FY2021E | M38: =M33 -> FY2022E
B39: Terminal growth | M39: =MIN(2%,3.5%) -> 0.02
B40: Terminal value | I40: TV=FCFF (2022)*(1+g)/(WACC-g) | M40: =M24*(1+M39)/(H31-M39) -> 302.16148
B41: Present value of terminal value | M41: =M40*M35 -> 230.51599
B43: Share price calculation | H43: FY 2017A
B44: Enterprise value (EV) for Walmart | H44: =SUM(I36:M36,M41) -> 283.01008
B45: Less: Short term debt | H45: ='Forecasted IS and BS'!H35 -> 3.92
B46: Less: Long term debt | H46: ='Forecasted IS and BS'!H40 -> 42.018
B47: Less: Other long term liabilities | H47: ='Forecasted IS and BS'!H41 -> 9.344
B48: Add: Cash and cash equivalents | H48: ='Forecasted IS and BS'!H22 -> 6.867
...

Sheet Sensitivity
A1: WAL-MART STORES, INC.
A2: DISCOUNTED CASH FLOW TECHNIQUE OF VALUATION
A3: USD bn
B5: Free cash flow to firm calculation (FCFF)
B6: Operating cash profit calculation | H6: FY 2017A | I6: FY2018E | J6: FY2019E | K6: FY2020E | L6: FY2021E | M6: FY2022E
B7: Revenues | I7: ='Forecasted IS and BS'!I6 -> 490.6168 | J7: ='Forecasted IS and BS'!J6 -> 496.38816 | K7: ='Forecasted IS and BS'!K6 -> 503.22018 | L7: ='Forecasted IS and BS'!L6 -> 511.15267 | M7: ='Forecasted IS and BS'!M6 -> 520.23252
B8: Less: Operating expenses (COGS + SGA) | I8: ='Forecasted IS and BS'!I7+'Forecasted IS and BS'!I9 -> 458.43337 | J8: ='Forecasted IS and BS'!J7+'Forecasted IS and BS'!J9 -> 464.81891 | K8: ='Forecasted IS and BS'!K7+'Forecasted IS and BS'!K9 -> 472.22287 | L8: ='Forecasted IS and BS'!L7+'Forecasted IS and BS'!L9 -> 480.68904 | M8: ='Forecasted IS and BS'!M7+'Forecasted IS and BS'!M9 -> 490.26821
B9: Less: Depreciation | I9: ='Forecasted IS and BS'!I10 -> 9.8777356 | J9: ='Forecasted IS and BS'!J10 -> 10.059065 | K9: ='Forecasted IS and BS'!K10 -> 10.263281 | L9: ='Forecasted IS and BS'!L10 -> 10.491608 | M9: ='Forecasted IS and BS'!M10 -> 10.745434
B10: Earnings before interest and tax (EBIT) | I10: =I7-I8-I9 -> 22.305702 | J10: =J7-J8-J9 -> 21.510185 | K10: =K7-K8-K9 -> 20.734031 | L10: =L7-L8-L9 -> 19.972024 | M10: =M7-M8-M9 -> 19.218873
B11: Less: Operating taxes | I11: ='Key ratios'!I11*Sensitivity!I10 -> 6.7514551 | J11: ='Key ratios'!J11*Sensitivity!J10 -> 6.5106694 | K11: ='Key ratios'!K11*Sensitivity!K10 -> 6.2757442 | L11: ='Key ratios'!L11*Sensitivity!L10 -> 6.045101 | M11: ='Key ratios'!M11*Sensitivity!M10 -> 5.8171384
B12: Post tax operating profit (NOPLAT) | I12: =I10-I11 -> 15.554247 | J12: =J10-J11 -> 14.999516 | K12: =K10-K11 -> 14.458287 | L12: =L10-L11 -> 13.926923 | M12: =M10-M11 -> 13.401734
B13: Add: Depreciation | I13: =I9 -> 9.8777356 | J13: =J9 -> 10.059065 | K13: =K9 -> 10.263281 | L13: =L9 -> 10.491608 | M13: =M9 -> 10.745434
B14: Post tax operating cash profit | I14: =I12+I13 -> 25.431983 | J14: =J12+J13 -> 25.058581 | K14: =K12+K13 -> 24.721568 | L14: =L12+L13 -> 24.418531 | M14: =M12+M13 -> 24.147168
B16: Operating cash investments | H16: =H6 -> FY 2017A | I16: =I6 -> FY2018E | J16: =J6 -> FY2019E | K16: =K6 -> FY2020E | L16: =L6 -> FY2021E | M16: =M6 -> FY2022E
B17: Capital expenditures investments | I17: 11.360304 | J17: 11.794927 | K17: 12.265162 | L17: 12.774047 | M17: 13.324935
B19: Working Capital | H19: -12.186 | I19: -11.997718 | J19: -11.790966 | K19: -11.564487 | L19: -11.316883 | M19: -11.046602
B20: Increase in working capital | I20: =I19-H19 -> 0.18828174 | J20: =J19-I19 -> 0.20675202 | K20: =K19-J19 -> 0.22647947 | L20: =L19-K19 -> 0.24760412 | M20: =M19-L19 -> 0.27028018
B21: Operating cash investments | I21: =I17+I20 -> 11.548585 | J21: =J17+J20 -> 12.001679 | K21: =K17+K20 -> 12.491641 | L21: =L17+L20 -> 13.021651 | M21: =M17+M20 -> 13.595215
B23: Free cash flow to firm | H23: =H16 -> FY 2017A | I23: =I16 -> FY2018E | J23: =J16 -> FY2019E | K23: =K16 -> FY2020E | L23: =L16 -> FY2021E | M23: =M16 -> FY2022E
B24: FCFF | I24: =I14-I21 -> 13.883397 | J24: =J14-J21 -> 13.056902 | K24: =K14-K21 -> 12.229927 | L24: =L14-L21 -> 11.396879 | M24: =M14-M21 -> 10.551953
B26: Cost of Capital calculation | H26: Percent
B27: Tax rate | H27: 0.31 | I27: 2017 tax rate
B28: Cost of debt | H28: 0.02 | I28: Bloomberg
B29: Cost of equity | H29: 0.063 | I29: Bloomberg
B30: Target capital structure (debt to capital) | H30: 0.15 | I30: Bloomberg
B31: WACC (Weighted average cost of capital) | H31: =H28*(1-H27)*H30+H29*(1-H30) -> 0.05562 | I31: WACC=% of debt in total capital*post tax cost of debt+% of equity*cost of equity
B33: Present value of future cash flows | H33: =H23 -> FY 2017A | I33: =I23 -> FY2018E | J33: =J23 -> FY2019E | K33: =K23 -> FY2020E | L33: =L23 -> FY2021E | M33: =M23 -> FY2022E
B34: Years from current | I34: 1 | J34: 2 | K34: 3 | L34: 4 | M34: 5
B35: Discount factor | I35: =1/(1+$H$31)^I34 -> 0.94731059 | J35: =1/(1+$H$31)^J34 -> 0.89739734 | K35: =1/(1+$H$31)^K34 -> 0.850114 | L35: =1/(1+$H$31)^L34 -> 0.80532199 | M35: =1/(1+$H$31)^M34 -> 0.76289005
B36: Present value of FCFF | I36: =I24*I35 -> 13.151889 | J36: =J24*J35 -> 11.717229 | K36: =K24*K35 -> 10.396832 | L36: =L24*L35 -> 9.1781577 | M36: =M24*M35 -> 8.04998
B38: Terminal value calculation | H38: =H33 -> FY 2017A | I38: =I33 -> FY2018E | J38: =J33 -> FY2019E | K38: =K33 -> FY2020E | L38: =L33 -> FY2021E | M38: =M33 -> FY2022E
B39: Terminal growth | M39: =MIN(2%,3.5%) -> 0.02
B40: Terminal value | I40: TV=FCFF (2022)*(1+g)/(WACC-g) | M40: =M24*(1+M39)/(H31-M39) -> 302.16148
B41: Present value of terminal value | M41: =M40*M35 -> 230.51599
B43: Share price calculation | H43: FY 2017A
B44: Enterprise value (EV) for Walmart | H44: =SUM(I36:M36,M41) -> 283.01008
B45: Less: Short term debt | H45: ='Forecasted IS and BS'!H35 -> 3.92
B46: Less: Long term debt | H46: ='Forecasted IS and BS'!H40 -> 42.018
B47: Less: Other long term liabilities | H47: ='Forecasted IS and BS'!H41 -> 9.344
B48: Add: Cash and cash equivalents | H48: ='Forecasted IS and BS'!H22 -> 6.867
...
